Workbook

Sheet สัปดาห์ที่ 1
A1: ใบเบิกจ่ายเงินค่าสอนพิเศษและค่าสอนเกินภาระงานสอนในสถานศึกษา
A2: แผนกวิชาช่างยนต์ | Z2: ลำดับ | AB2: รายชื่อ | AE2: รวม ชม./ ส. | AH2: รวม ค่าสอน / สัปดาห์
A3: ระหว่างวันที่ | D3: 14 | E3: เดือน | F3: กันยายน | H3: พ.ศ. 2569 | I3: ถึง วันที่ | J3: 18 | K3: เดือน | L3: กันยายน | N3: พ.ศ. 2569 | Z3: 1 | AB3: นายชำนาญ แก้วจงประสิทธิ์ | AE3: 12 | AH3: 2400
G4: ü | H4: ครู | I4: หน้าที่พิเศษ | J4: หัวหน้าแผนกวิชาช่างยนต์ | Z4: 2 | AB4: นายวัชรัศนิ์ ไชยศาสตร์ | AE4: 12 | AH4: 2400
A5: ที่ | B5: ชื่อ-สกุล | E5: ตำแหน่ง | F5: ระยะเวลาที่สอน | H5: รหัสวิชา | I5: ชั้น,แผนก,ห้อง | J5: เวลาสอน | L5: ปวช.(คาบ) | N5: เงิน | O5: ยอดเงิน | P5: ปวส.(คาบ) | R5: เงิน | S5: ยอดเงิน | Z5: 3 | AB5: นายไพรัช น้อยแสง | AE5: 12 | AH5: 2400
F6: ส. | G6: วดป. | L6: ใน | M6: นอก | N6: ต่อ ชม. | O6: (บาท) | P6: ใน | Q6: นอก | R6: ต่อ ชม. | S6: (บาท) | Z6: 4 | AB6: นายจักรกฤษณ์ ปัญญา | AE6: 12 | AH6: 2400
A7: 1 | B7: =AB3 | E7: ครู | F7: 1 | G7: จันทร์ | H7: 20101-2018 | I7: ชย.3/3 (26) | J7: 17:10 - 21:10 | L7: 4 | Z7: 5 | AB7: นายพลกฤต น้อยเกิด | AE7: 12 | AH7: 2400
G8: 14 ก.ย.69 | Z8: 6 | AB8: นายพงษ์พัฒน์ พิมพ์ปรุ | AE8: 12 | AH8: 2400
Z9: 7 | AB9: นายพงศ์ศิริ ธรรมาวุฒิ | AE9: 12 | AH9: 2400
Z10: 8 | AB10: นายศุภเดช เมืองเงิน | AE10: 12 | AH10: 2400
Z11: 9 | AB11: นายณัฐพงศ์ จันทร์แดง | AE11: 12 | AH11: 2400
G12: อังคาร | H12: 20101-2010 | I12: ชย.2/7 (26) | J12: 08:10 - 12:10 | L12: 4 | Z12: 10 | AB12: นายมนตรี ทิมสุข | AE12: 12 | AH12: 2400
G13: 15 ก.ย.69 | H13: 20101-2010 | I13: ชย.2/7 (26) | J13: 13:10 - 16:10 | L13: 3 | Z13: 11 | AB13: นางสาวจิราพร พิมเสน | AE13: 12 | AH13: 2400
H14: 20101-2018 | I14: ชย.3/3 (26) | J14: 17:10 - 20:10 | L14: 3 | Z14: 12 | AB14: นายสมชาย อุประ | AE14: 12 | AH14: 2400
Z15: 13 | AB15: นายสถาปนิก คุ้มสะอาด | AE15: 12 | AH15: 2400
G17: พุธ | H17: 20101-2010 | I17: ชย.2/6 (26) | J17: 08:10 - 12:10 | L17: 2 | M17: 2 | N17: 200 | O17: =M17*N17
G18: 16 ก.ย.69 | H18: 20101-2010 | I18: ชย.2/6 (26) | J18: 13:10 - 16:10 | M18: 3 | N18: 200 | O18: =M18*N18
G22: พฤหัส | H22: 20101-2010 | I22: ชย.2/5 (26) | J22: 08:10 - 12:10 | M22: 4 | N22: 200 | O22: =M22*N22
G23: 17 ก.ย.69 | H23: 20101-2010 | I23: ชย.2/5 (26) | J23: 15:10 - 18:10 | M23: 3 | N23: 200 | O23: =M23*N23
G27: ศุกร์
G28: 18 ก.ย.69
G32: รวมขั่วโมงที่สอนแยก ภาระงาน/ เกินภาระงาน | L32: =SUM(L7:L31) | M32: =SUM(M7:M31) | P32: =SUM(P7:P31) | Q32: =SUM(Q7:Q31)
G33: รวมจำนวนชั่วโมงสอนคาบต่อสับดาห์ | L33: =L32+M32 | P33: =P32+Q32
G34: จำนวนชั่วโมงสอนตามภาระงานสอน | L34: 12 | P34: 0
G35: จำนวนชั่วโมงบิกเกินภาระงานสอน/ค่าสอน | L35: 0 | M35: =SUM(M7:M31) | O35: =SUM(O7:O31) | P35: 0 | Q35: =SUM(Q7:Q31) | S35: =SUM(S7:S31)
A36: รวมจำนวนหน่วยชั่วโมงที่ขอเบิกค่าสอน …. | H36: =M35+Q35 | I36: ….ชั่วโมง | K36: ยอดเงินรวม | P36: =S35+O35 | S36: ..บาท
A37: ผู้ขอเบิก | H37: ผู้รับรอง | M37: ผู้ตรวจ
A38: ลงชื่อ…………………………………………… | H38: ลงชื่อ…………………………………………… | M38: ลงชื่อ……………………………………………
A39: ( | B39: =B7 | G39: ) | H39: ( | I39: นายชำนาญ แก้วจงประสิทธิ์ | L39: ) | M39: ( | O39: นายทศวรรษ คำสม | S39: )
A40: ตำแหน่ง ครู | H40: ตำแหน่ง หัวหน้าแผนก | M40: ตำแหน่ง ผู้ตรวจสอบ
A41: วันที่ 22 เดือน กันยายน พ.ศ.2569 | H41: =A41 | M41: =A41
A42: ผู้ตรวจ | J42: ผู้เห็นชอบ
A43: ลงชื่อ…………………………………………… | J43: ลงชื่อ……………………………………………
B44: (นายศิวรักษ์ บุญประเสริฐ) | L44: (นายฉัตรชัย งาหอม)
A45: ตำแหน่งครู หัวหน้างานพัฒนาหลักสูตร ฯ | J45: ตำแหน่ง รองผู้อำนวยการฝ่ายวิชาการ
A46: วันที่.......เดือน..........................พ.ศ.............. | J46: วันที่.......เดือน..........................พ.ศ..............
A47: ใบเบิกจ่ายเงินค่าสอนพิเศษและค่าสอนเกินภาระงานสอนในสถานศึกษา
A48: แผนกวิชาช่างยนต์
A49: ระหว่างวันที่ | D49: =D3 | E49: เดือน | F49: =F3 | H49: =H3 | I49: ถึง วันที่ | J49: =J3 | K49: เดือน | L49: =L3 | N49: =N3
G50: ü | H50: ครู | I50: หน้าที่พิเศษ | J50: หัวงานทวิภาคี
...

Sheet สัปดาห์ที่ 2
A1: ใบเบิกจ่ายเงินค่าสอนพิเศษและค่าสอนเกินภาระงานสอนในสถานศึกษา
A2: แผนกวิชาช่างยนต์ | Z2: ลำดับ | AB2: รายชื่อ | AE2: รวม ชม./ ส. | AH2: รวม ค่าสอน / สัปดาห์
A3: ระหว่างวันที่ | D3: 21 | E3: เดือน | F3: กันยายน | H3: พ.ศ. 2569 | I3: ถึง วันที่ | J3: 25 | K3: เดือน | L3: กันยายน | N3: พ.ศ. 2569 | Z3: 1 | AB3: นายชำนาญ แก้วจงประสิทธิ์ | AE3: 12 | AH3: 2400
G4: ü | H4: ครู | I4: หน้าที่พิเศษ | J4: หัวหน้าแผนกวิชาช่างยนต์ | Z4: 2 | AB4: นายวัชรัศนิ์ ไชยศาสตร์ | AE4: 12 | AH4: 2400
A5: ที่ | B5: ชื่อ-สกุล | E5: ตำแหน่ง | F5: ระยะเวลาที่สอน | H5: รหัสวิชา | I5: ชั้น,แผนก,ห้อง | J5: เวลาสอน | L5: ปวช.(คาบ) | N5: เงิน | O5: ยอดเงิน | P5: ปวส.(คาบ) | R5: เงิน | S5: ยอดเงิน | Z5: 3 | AB5: นายไพรัช น้อยแสง | AE5: 12 | AH5: 2400
F6: ส. | G6: วดป. | L6: ใน | M6: นอก | N6: ต่อ ชม. | O6: (บาท) | P6: ใน | Q6: นอก | R6: ต่อ ชม. | S6: (บาท) | Z6: 4 | AB6: นายจักรกฤษณ์ ปัญญา | AE6: 12 | AH6: 2400
A7: 1 | B7: =AB3 | E7: ครู | F7: 2 | G7: จันทร์ | H7: หยุด | O7: =M7*N7 | S7: =Q7*R7 | Z7: 5 | AB7: นายพลกฤต น้อยเกิด | AE7: 12 | AH7: 2400
G8: 21 ก.ย.69 | O8: =M8*N8 | S8: =Q8*R8 | Z8: 6 | AB8: นายพงษ์พัฒน์ พิมพ์ปรุ | AE8: 12 | AH8: 2400
O9: =M9*N9 | S9: =Q9*R9 | Z9: 7 | AB9: นายพงศ์ศิริ ธรรมาวุฒิ | AE9: 12 | AH9: 2400
O10: =M10*N10 | S10: =Q10*R10 | Z10: 8 | AB10: นายศุภเดช เมืองเงิน | AE10: 12 | AH10: 2400
O11: =M11*N11 | S11: =Q11*R11 | Z11: 9 | AB11: นายณัฐพงศ์ จันทร์แดง | AE11: 12 | AH11: 2400
G12: อังคาร | H12: 20101-2010 | I12: ชย.2/7 (26) | J12: 08:10 - 12:10 | L12: 4 | Z12: 10 | AB12: นายมนตรี ทิมสุข | AE12: 12 | AH12: 2400
G13: 22 ก.ย.69 | H13: 20101-2010 | I13: ชย.2/7 (26) | J13: 13:10 - 16:10 | L13: 3 | Z13: 11 | AB13: นางสาวจิราพร พิมเสน | AE13: 12 | AH13: 2400
H14: 20101-2018 | I14: ชย.3/3 (26) | J14: 17:10 - 20:10 | L14: 3 | Z14: 12 | AB14: นายสมชาย อุประ | AE14: 12 | AH14: 2400
Z15: 13 | AB15: นายสถาปนิก คุ้มสะอาด | AE15: 12 | AH15: 2400
G17: พุธ | H17: 20101-2010 | I17: ชย.2/6 (26) | J17: 08:10 - 12:10 | L17: 2 | M17: 2 | N17: 200 | O17: =M17*N17
G18: 23 ก.ย.69 | H18: 20101-2010 | I18: ชย.2/6 (26) | J18: 13:10 - 16:10 | M18: 3 | N18: 200 | O18: =M18*N18
G22: พฤหัส | H22: 20101-2010 | I22: ชย.2/5 (26) | J22: 08:10 - 12:10 | M22: 4 | N22: 200 | O22: =M22*N22
G23: 24 ก.ย.69 | H23: 20101-2010 | I23: ชย.2/5 (26) | J23: 15:10 - 18:10 | M23: 3 | N23: 200 | O23: =M23*N23
G27: ศุกร์
G28: 25 ก.ย.69
G32: รวมขั่วโมงที่สอนแยก ภาระงาน/ เกินภาระงาน | L32: =SUM(L7:L31) | M32: =SUM(M7:M31) | P32: =SUM(P7:P31) | Q32: =SUM(Q7:Q31)
G33: รวมจำนวนชั่วโมงสอนคาบต่อสับดาห์ | L33: =L32+M32 | P33: =P32+Q32
G34: จำนวนชั่วโมงสอนตามภาระงานสอน | L34: 12 | P34: 0
G35: จำนวนชั่วโมงบิกเกินภาระงานสอน/ค่าสอน | L35: 0 | M35: =SUM(M7:M31) | O35: =SUM(O7:O31) | P35: 0 | Q35: =SUM(Q7:Q31) | S35: =SUM(S7:S31)
A36: รวมจำนวนหน่วยชั่วโมงที่ขอเบิกค่าสอน …. | H36: =M35+Q35 | I36: ….ชั่วโมง | K36: ยอดเงินรวม | P36: =S35+O35 | S36: ..บาท
A37: ผู้ขอเบิก | H37: ผู้รับรอง | M37: ผู้ตรวจ
A38: ลงชื่อ…………………………………………… | H38: ลงชื่อ…………………………………………… | M38: ลงชื่อ……………………………………………
A39: ( | B39: =B7 | G39: ) | H39: ( | I39: นายชำนาญ แก้วจงประสิทธิ์ | L39: ) | M39: ( | O39: นายทศวรรษ คำสม | S39: )
A40: ตำแหน่ง ครู | H40: ตำแหน่ง หัวหน้าแผนก | M40: ตำแหน่ง ผู้ตรวจสอบ
A41: วันที่ 28 เดือน กันยายน พ.ศ.2569 | H41: =A41 | M41: =A41
A42: ผู้ตรวจ | J42: ผู้เห็นชอบ
A43: ลงชื่อ…………………………………………… | J43: ลงชื่อ……………………………………………
B44: (นายศิวรักษ์ บุญประเสริฐ) | L44: (นายฉัตรชัย งาหอม)
A45: ตำแหน่งครู หัวหน้างานพัฒนาหลักสูตร ฯ | J45: ตำแหน่ง รองผู้อำนวยการฝ่ายวิชาการ
A46: วันที่.......เดือน..........................พ.ศ.............. | J46: วันที่.......เดือน..........................พ.ศ..............
A47: ใบเบิกจ่ายเงินค่าสอนพิเศษและค่าสอนเกินภาระงานสอนในสถานศึกษา
A48: แผนกวิชาช่างยนต์
A49: ระหว่างวันที่ | D49: =D3 | E49: เดือน | F49: =F3 | H49: =H3 | I49: ถึง วันที่ | J49: =J3 | K49: เดือน | L49: =L3 | N49: =N3
G50: ü | H50: ครู | I50: หน้าที่พิเศษ | J50: หัวงานทวิภาคี
...

Sheet สัปดาห์ที่ 3
A1: ใบเบิกจ่ายเงินค่าสอนพิเศษและค่าสอนเกินภาระงานสอนในสถานศึกษา
A2: แผนกวิชาช่างยนต์ | Z2: ลำดับ | AB2: รายชื่อ | AE2: รวม ชม./ ส. | AH2: รวม ค่าสอน / สัปดาห์
A3: ระหว่างวันที่ | D3: 28 | E3: เดือน | F3: กันยายน | H3: พ.ศ. 2569 | I3: ถึง วันที่ | J3: 2 | K3: เดือน | L3: ตุลาคม | N3: พ.ศ. 2569 | Z3: 1 | AB3: นายชำนาญ แก้วจงประสิทธิ์ | AE3: 12 | AH3: 2400
G4: ü | H4: ครู | I4: หน้าที่พิเศษ | J4: หัวหน้าแผนกวิชาช่างยนต์ | Z4: 2 | AB4: นายวัชรัศนิ์ ไชยศาสตร์ | AE4: 12 | AH4: 2400
A5: ที่ | B5: ชื่อ-สกุล | E5: ตำแหน่ง | F5: ระยะเวลาที่สอน | H5: รหัสวิชา | I5: ชั้น,แผนก,ห้อง | J5: เวลาสอน | L5: ปวช.(คาบ) | N5: เงิน | O5: ยอดเงิน | P5: ปวส.(คาบ) | R5: เงิน | S5: ยอดเงิน | Z5: 3 | AB5: นายไพรัช น้อยแสง | AE5: 12 | AH5: 2400
F6: ส. | G6: วดป. | L6: ใน | M6: นอก | N6: ต่อ ชม. | O6: (บาท) | P6: ใน | Q6: นอก | R6: ต่อ ชม. | S6: (บาท) | Z6: 4 | AB6: นายจักรกฤษณ์ ปัญญา | AE6: 12 | AH6: 2400
A7: 1 | B7: =AB3 | E7: ครู | F7: 3 | G7: จันทร์ | H7: 20101-2018 | I7: ชย.3/3 (26) | J7: 17:10 - 21:10 | L7: 4 | Z7: 5 | AB7: นายพลกฤต น้อยเกิด | AE7: 12 | AH7: 2400
G8: 28 ก.ย.69 | Z8: 6 | AB8: นายพงษ์พัฒน์ พิมพ์ปรุ | AE8: 12 | AH8: 2400
Z9: 7 | AB9: นายพงศ์ศิริ ธรรมาวุฒิ | AE9: 12 | AH9: 2400
Z10: 8 | AB10: นายศุภเดช เมืองเงิน | AE10: 12 | AH10: 2400
Z11: 9 | AB11: นายณัฐพงศ์ จันทร์แดง | AE11: 12 | AH11: 2400
G12: อังคาร | H12: 20101-2010 | I12: ชย.2/7 (26) | J12: 08:10 - 12:10 | L12: 4 | Z12: 10 | AB12: นายมนตรี ทิมสุข | AE12: 12 | AH12: 2400
G13: 29 ก.ย.69 | H13: 20101-2010 | I13: ชย.2/7 (26) | J13: 13:10 - 16:10 | L13: 3 | Z13: 11 | AB13: นางสาวจิราพร พิมเสน | AE13: 12 | AH13: 2400
H14: 20101-2018 | I14: ชย.3/3 (26) | J14: 17:10 - 20:10 | L14: 3 | Z14: 12 | AB14: นายสมชาย อุประ | AE14: 12 | AH14: 2400
Z15: 13 | AB15: นายสถาปนิก คุ้มสะอาด | AE15: 12 | AH15: 2400
G17: พุธ | H17: 20101-2010 | I17: ชย.2/6 (26) | J17: 08:10 - 12:10 | L17: 2 | M17: 2 | N17: 200 | O17: =M17*N17
G18: 30 ก.ย.69 | H18: 20101-2010 | I18: ชย.2/6 (26) | J18: 13:10 - 16:10 | M18: 3 | N18: 200 | O18: =M18*N18
G22: พฤหัส | H22: 20101-2010 | I22: ชย.2/5 (26) | J22: 08:10 - 12:10 | M22: 4 | N22: 200 | O22: =M22*N22
G23: 1 ต.ค.69 | H23: 20101-2010 | I23: ชย.2/5 (26) | J23: 15:10 - 18:10 | M23: 3 | N23: 200 | O23: =M23*N23
G27: ศุกร์
G28: 2 ต.ค.69
G32: รวมขั่วโมงที่สอนแยก ภาระงาน/ เกินภาระงาน | L32: =SUM(L7:L31) | M32: =SUM(M7:M31) | P32: =SUM(P7:P31) | Q32: =SUM(Q7:Q31)
G33: รวมจำนวนชั่วโมงสอนคาบต่อสับดาห์ | L33: =L32+M32 | P33: =P32+Q32
G34: จำนวนชั่วโมงสอนตามภาระงานสอน | L34: 12 | P34: 0
G35: จำนวนชั่วโมงบิกเกินภาระงานสอน/ค่าสอน | L35: 0 | M35: =SUM(M7:M31) | O35: =SUM(O7:O31) | P35: 0 | Q35: =SUM(Q7:Q31) | S35: =SUM(S7:S31)
A36: รวมจำนวนหน่วยชั่วโมงที่ขอเบิกค่าสอน …. | H36: =M35+Q35 | I36: ….ชั่วโมง | K36: ยอดเงินรวม | P36: =S35+O35 | S36: ..บาท
A37: ผู้ขอเบิก | H37: ผู้รับรอง | M37: ผู้ตรวจ
A38: ลงชื่อ…………………………………………… | H38: ลงชื่อ…………………………………………… | M38: ลงชื่อ……………………………………………
A39: ( | B39: =B7 | G39: ) | H39: ( | I39: นายชำนาญ แก้วจงประสิทธิ์ | L39: ) | M39: ( | O39: นายทศวรรษ คำสม | S39: )
A40: ตำแหน่ง ครู | H40: ตำแหน่ง หัวหน้าแผนก | M40: ตำแหน่ง ผู้ตรวจสอบ
A41: วันที่ 5 เดือน ตุลาคม พ.ศ.2569 | H41: =A41 | M41: =A41
A42: ผู้ตรวจ | J42: ผู้เห็นชอบ
A43: ลงชื่อ…………………………………………… | J43: ลงชื่อ……………………………………………
B44: (นายศิวรักษ์ บุญประเสริฐ) | L44: (นายฉัตรชัย งาหอม)
A45: ตำแหน่งครู หัวหน้างานพัฒนาหลักสูตร ฯ | J45: ตำแหน่ง รองผู้อำนวยการฝ่ายวิชาการ
A46: วันที่.......เดือน..........................พ.ศ.............. | J46: วันที่.......เดือน..........................พ.ศ..............
A47: ใบเบิกจ่ายเงินค่าสอนพิเศษและค่าสอนเกินภาระงานสอนในสถานศึกษา
A48: แผนกวิชาช่างยนต์
A49: ระหว่างวันที่ | D49: =D3 | E49: เดือน | F49: =F3 | H49: =H3 | I49: ถึง วันที่ | J49: =J3 | K49: เดือน | L49: =L3 | N49: =N3
G50: ü | H50: ครู | I50: หน้าที่พิเศษ | J50: หัวงานทวิภาคี
...

Sheet สัปดาห์ที่ 4
A1: ใบเบิกจ่ายเงินค่าสอนพิเศษและค่าสอนเกินภาระงานสอนในสถานศึกษา
A2: แผนกวิชาช่างยนต์ | Z2: ลำดับ | AB2: รายชื่อ | AE2: รวม ชม./ ส. | AH2: รวม ค่าสอน / สัปดาห์
A3: ระหว่างวันที่ | D3: 5 | E3: เดือน | F3: ตุลาคม | H3: พ.ศ. 2569 | I3: ถึง วันที่ | J3: 9 | K3: เดือน | L3: ตุลาคม | N3: พ.ศ. 2569 | Z3: 1 | AB3: นายชำนาญ แก้วจงประสิทธิ์ | AE3: 12 | AH3: 2400
G4: ü | H4: ครู | I4: หน้าที่พิเศษ | J4: หัวหน้าแผนกวิชาช่างยนต์ | Z4: 2 | AB4: นายวัชรัศนิ์ ไชยศาสตร์ | AE4: 12 | AH4: 2400
A5: ที่ | B5: ชื่อ-สกุล | E5: ตำแหน่ง | F5: ระยะเวลาที่สอน | H5: รหัสวิชา | I5: ชั้น,แผนก,ห้อง | J5: เวลาสอน | L5: ปวช.(คาบ) | N5: เงิน | O5: ยอดเงิน | P5: ปวส.(คาบ) | R5: เงิน | S5: ยอดเงิน | Z5: 3 | AB5: นายไพรัช น้อยแสง | AE5: 12 | AH5: 2400
F6: ส. | G6: วดป. | L6: ใน | M6: นอก | N6: ต่อ ชม. | O6: (บาท) | P6: ใน | Q6: นอก | R6: ต่อ ชม. | S6: (บาท) | Z6: 4 | AB6: นายจักรกฤษณ์ ปัญญา | AE6: 12 | AH6: 2400
A7: 1 | B7: =AB3 | E7: ครู | F7: 4 | G7: จันทร์ | H7: 20101-2018 | I7: ชย.3/3 (26) | J7: 17:10 - 21:10 | L7: 4 | Z7: 5 | AB7: นายพลกฤต น้อยเกิด | AE7: 12 | AH7: 2400
G8: 5 ต.ค.69 | Z8: 6 | AB8: นายพงษ์พัฒน์ พิมพ์ปรุ | AE8: 12 | AH8: 2400
Z9: 7 | AB9: นายพงศ์ศิริ ธรรมาวุฒิ | AE9: 12 | AH9: 2400
Z10: 8 | AB10: นายศุภเดช เมืองเงิน | AE10: 12 | AH10: 2400
Z11: 9 | AB11: นายณัฐพงศ์ จันทร์แดง | AE11: 12 | AH11: 2400
G12: อังคาร | H12: 20101-2010 | I12: ชย.2/7 (26) | J12: 08:10 - 12:10 | L12: 4 | Z12: 10 | AB12: นายมนตรี ทิมสุข | AE12: 12 | AH12: 2400
G13: 6 ต.ค.69 | H13: 20101-2010 | I13: ชย.2/7 (26) | J13: 13:10 - 16:10 | L13: 3 | Z13: 11 | AB13: นางสาวจิราพร พิมเสน | AE13: 12 | AH13: 2400
H14: 20101-2018 | I14: ชย.3/3 (26) | J14: 17:10 - 20:10 | L14: 3 | Z14: 12 | AB14: นายสมชาย อุประ | AE14: 12 | AH14: 2400
Z15: 13 | AB15: นายสถาปนิก คุ้มสะอาด | AE15: 12 | AH15: 2400
G17: พุธ | H17: 20101-2010 | I17: ชย.2/6 (26) | J17: 08:10 - 12:10 | L17: 2 | M17: 2 | N17: 200 | O17: =M17*N17
G18: 7 ต.ค.69 | H18: 20101-2010 | I18: ชย.2/6 (26) | J18: 13:10 - 16:10 | M18: 3 | N18: 200 | O18: =M18*N18
G22: พฤหัส | H22: 20101-2010 | I22: ชย.2/5 (26) | J22: 08:10 - 12:10 | M22: 4 | N22: 200 | O22: =M22*N22
G23: 8 ต.ค.69 | H23: 20101-2010 | I23: ชย.2/5 (26) | J23: 15:10 - 18:10 | M23: 3 | N23: 200 | O23: =M23*N23
G27: ศุกร์
G28: 9 ต.ค.69
G32: รวมขั่วโมงที่สอนแยก ภาระงาน/ เกินภาระงาน | L32: =SUM(L7:L31) | M32: =SUM(M7:M31) | P32: =SUM(P7:P31) | Q32: =SUM(Q7:Q31)
G33: รวมจำนวนชั่วโมงสอนคาบต่อสับดาห์ | L33: =L32+M32 | P33: =P32+Q32
G34: จำนวนชั่วโมงสอนตามภาระงานสอน | L34: 12 | P34: 0
G35: จำนวนชั่วโมงบิกเกินภาระงานสอน/ค่าสอน | L35: 0 | M35: =SUM(M7:M31) | O35: =SUM(O7:O31) | P35: 0 | Q35: =SUM(Q7:Q31) | S35: =SUM(S7:S31)
A36: รวมจำนวนหน่วยชั่วโมงที่ขอเบิกค่าสอน …. | H36: =M35+Q35 | I36: ….ชั่วโมง | K36: ยอดเงินรวม | P36: =S35+O35 | S36: ..บาท
A37: ผู้ขอเบิก | H37: ผู้รับรอง | M37: ผู้ตรวจ
A38: ลงชื่อ…………………………………………… | H38: ลงชื่อ…………………………………………… | M38: ลงชื่อ……………………………………………
A39: ( | B39: =B7 | G39: ) | H39: ( | I39: นายชำนาญ แก้วจงประสิทธิ์ | L39: ) | M39: ( | O39: นายทศวรรษ คำสม | S39: )
A40: ตำแหน่ง ครู | H40: ตำแหน่ง หัวหน้าแผนก | M40: ตำแหน่ง ผู้ตรวจสอบ
A41: วันที่ 12 เดือน ตุลาคม พ.ศ.2569 | H41: =A41 | M41: =A41
A42: ผู้ตรวจ | J42: ผู้เห็นชอบ
A43: ลงชื่อ…………………………………………… | J43: ลงชื่อ……………………………………………
B44: (นายศิวรักษ์ บุญประเสริฐ) | L44: (นายฉัตรชัย งาหอม)
A45: ตำแหน่งครู หัวหน้างานพัฒนาหลักสูตร ฯ | J45: ตำแหน่ง รองผู้อำนวยการฝ่ายวิชาการ
A46: วันที่.......เดือน..........................พ.ศ.............. | J46: วันที่.......เดือน..........................พ.ศ..............
A47: ใบเบิกจ่ายเงินค่าสอนพิเศษและค่าสอนเกินภาระงานสอนในสถานศึกษา
A48: แผนกวิชาช่างยนต์
A49: ระหว่างวันที่ | D49: =D3 | E49: เดือน | F49: =F3 | H49: =H3 | I49: ถึง วันที่ | J49: =J3 | K49: เดือน | L49: =L3 | N49: =N3
G50: ü | H50: ครู | I50: หน้าที่พิเศษ | J50: หัวงานทวิภาคี
...

Sheet สัปดาห์ที่ 5
A1: ใบเบิกจ่ายเงินค่าสอนพิเศษและค่าสอนเกินภาระงานสอนในสถานศึกษา
A2: แผนกวิชาช่างยนต์ | Z2: ลำดับ | AB2: รายชื่อ | AE2: รวม ชม./ ส. | AH2: รวม ค่าสอน / สัปดาห์
A3: ระหว่างวันที่ | D3: 12 | E3: เดือน | F3: ตุลาคม | H3: พ.ศ. 2569 | I3: ถึง วันที่ | J3: 16 | K3: เดือน | L3: ตุลาคม | N3: พ.ศ. 2569 | Z3: 1 | AB3: นายชำนาญ แก้วจงประสิทธิ์ | AE3: 12 | AH3: 2400
G4: ü | H4: ครู | I4: หน้าที่พิเศษ | J4: หัวหน้าแผนกวิชาช่างยนต์ | Z4: 2 | AB4: นายวัชรัศนิ์ ไชยศาสตร์ | AE4: 12 | AH4: 2400
A5: ที่ | B5: ชื่อ-สกุล | E5: ตำแหน่ง | F5: ระยะเวลาที่สอน | H5: รหัสวิชา | I5: ชั้น,แผนก,ห้อง | J5: เวลาสอน | L5: ปวช.(คาบ) | N5: เงิน | O5: ยอดเงิน | P5: ปวส.(คาบ) | R5: เงิน | S5: ยอดเงิน | Z5: 3 | AB5: นายไพรัช น้อยแสง | AE5: 12 | AH5: 2400
F6: ส. | G6: วดป. | L6: ใน | M6: นอก | N6: ต่อ ชม. | O6: (บาท) | P6: ใน | Q6: นอก | R6: ต่อ ชม. | S6: (บาท) | Z6: 4 | AB6: นายจักรกฤษณ์ ปัญญา | AE6: 12 | AH6: 2400
A7: 1 | B7: =AB3 | E7: ครู | F7: 5 | G7: จันทร์ | H7: 20101-2018 | I7: ชย.3/3 (26) | J7: 17:10 - 21:10 | L7: 4 | Z7: 5 | AB7: นายพลกฤต น้อยเกิด | AE7: 12 | AH7: 2400
G8: 12 ต.ค.69 | Z8: 6 | AB8: นายพงษ์พัฒน์ พิมพ์ปรุ | AE8: 12 | AH8: 2400
Z9: 7 | AB9: นายพงศ์ศิริ ธรรมาวุฒิ | AE9: 12 | AH9: 2400
Z10: 8 | AB10: นายศุภเดช เมืองเงิน | AE10: 12 | AH10: 2400
Z11: 9 | AB11: นายณัฐพงศ์ จันทร์แดง | AE11: 12 | AH11: 2400
G12: อังคาร | H12: 20101-2010 | I12: ชย.2/7 (26) | J12: 08:10 - 12:10 | L12: 4 | Z12: 10 | AB12: นายมนตรี ทิมสุข | AE12: 12 | AH12: 2400
G13: 13 ต.ค.69 | H13: 20101-2010 | I13: ชย.2/7 (26) | J13: 13:10 - 16:10 | L13: 3 | Z13: 11 | AB13: นางสาวจิราพร พิมเสน | AE13: 12 | AH13: 2400
H14: 20101-2018 | I14: ชย.3/3 (26) | J14: 17:10 - 20:10 | L14: 3 | Z14: 12 | AB14: นายสมชาย อุประ | AE14: 12 | AH14: 2400
Z15: 13 | AB15: นายสถาปนิก คุ้มสะอาด | AE15: 12 | AH15: 2400
G17: พุธ | H17: 20101-2010 | I17: ชย.2/6 (26) | J17: 08:10 - 12:10 | L17: 2 | M17: 2 | N17: 200 | O17: =M17*N17
G18: 14 ต.ค.69 | H18: 20101-2010 | I18: ชย.2/6 (26) | J18: 13:10 - 16:10 | M18: 3 | N18: 200 | O18: =M18*N18
G22: พฤหัส | H22: 20101-2010 | I22: ชย.2/5 (26) | J22: 08:10 - 12:10 | M22: 4 | N22: 200 | O22: =M22*N22
G23: 15 ต.ค.69 | H23: 20101-2010 | I23: ชย.2/5 (26) | J23: 15:10 - 18:10 | M23: 3 | N23: 200 | O23: =M23*N23
G27: ศุกร์
G28: 16 ต.ค.69
G32: รวมขั่วโมงที่สอนแยก ภาระงาน/ เกินภาระงาน | L32: =SUM(L7:L31) | M32: =SUM(M7:M31) | P32: =SUM(P7:P31) | Q32: =SUM(Q7:Q31)
G33: รวมจำนวนชั่วโมงสอนคาบต่อสับดาห์ | L33: =L32+M32 | P33: =P32+Q32
G34: จำนวนชั่วโมงสอนตามภาระงานสอน | L34: 12 | P34: 0
G35: จำนวนชั่วโมงบิกเกินภาระงานสอน/ค่าสอน | L35: 0 | M35: =SUM(M7:M31) | O35: =SUM(O7:O31) | P35: 0 | Q35: =SUM(Q7:Q31) | S35: =SUM(S7:S31)
A36: รวมจำนวนหน่วยชั่วโมงที่ขอเบิกค่าสอน …. | H36: =M35+Q35 | I36: ….ชั่วโมง | K36: ยอดเงินรวม | P36: =S35+O35 | S36: ..บาท
A37: ผู้ขอเบิก | H37: ผู้รับรอง | M37: ผู้ตรวจ
A38: ลงชื่อ…………………………………………… | H38: ลงชื่อ…………………………………………… | M38: ลงชื่อ……………………………………………
A39: ( | B39: =B7 | G39: ) | H39: ( | I39: นายชำนาญ แก้วจงประสิทธิ์ | L39: ) | M39: ( | O39: นายทศวรรษ คำสม | S39: )
A40: ตำแหน่ง ครู | H40: ตำแหน่ง หัวหน้าแผนก | M40: ตำแหน่ง ผู้ตรวจสอบ
A41: วันที่ 19 เดือน ตุลาคม พ.ศ.2569 | H41: =A41 | M41: =A41
A42: ผู้ตรวจ | J42: ผู้เห็นชอบ
A43: ลงชื่อ…………………………………………… | J43: ลงชื่อ……………………………………………
B44: (นายศิวรักษ์ บุญประเสริฐ) | L44: (นายฉัตรชัย งาหอม)
A45: ตำแหน่งครู หัวหน้างานพัฒนาหลักสูตร ฯ | J45: ตำแหน่ง รองผู้อำนวยการฝ่ายวิชาการ
A46: วันที่.......เดือน..........................พ.ศ.............. | J46: วันที่.......เดือน..........................พ.ศ..............
A47: ใบเบิกจ่ายเงินค่าสอนพิเศษและค่าสอนเกินภาระงานสอนในสถานศึกษา
A48: แผนกวิชาช่างยนต์
A49: ระหว่างวันที่ | D49: =D3 | E49: เดือน | F49: =F3 | H49: =H3 | I49: ถึง วันที่ | J49: =J3 | K49: เดือน | L49: =L3 | N49: =N3
G50: ü | H50: ครู | I50: หน้าที่พิเศษ | J50: หัวงานทวิภาคี
...

Sheet ตารางแจงเงินรายบุคคล
D2: แผนกช่างยนต์
D4: ครูประจำ
A5: ลำดับ | B5: ชื่อ-สกุล | C5: 1 | E5: 2 | G5: 3 | I5: 4 | K5: 5 | M5: 6 | O5: รวม / ชม. | P5: รวม / เงิน
C6: ชม/ส | D6: เงิน | E6: ชม/ส | F6: เงิน | G6: ชม/ส | H6: เงิน | I6: ชม/ส | J6: เงิน | K6: ชม/ส | L6: เงิน | M6: ชม/ส | N6: เงิน
A7: 1 | B7: ='สัปดาห์ที่ 1'!AB3 | C7: ='สัปดาห์ที่ 1'!AE3 | D7: ='สัปดาห์ที่ 1'!AH3 | E7: ='สัปดาห์ที่ 2'!AE3 | F7: ='สัปดาห์ที่ 2'!AH3 | G7: ='สัปดาห์ที่ 3'!AE3 | H7: ='สัปดาห์ที่ 3'!AH3 | I7: ='สัปดาห์ที่ 4'!AE3 | J7: ='สัปดาห์ที่ 4'!AH3 | K7: ='สัปดาห์ที่ 5'!AE3 | L7: ='สัปดาห์ที่ 5'!AH3 | M7: 0 | N7: 0 | O7: =C7+E7+G7+I7+K7 | P7: =D7+F7+H7+J7+L7
A8: 2 | B8: ='สัปดาห์ที่ 1'!AB4 | C8: ='สัปดาห์ที่ 1'!AE4 | D8: ='สัปดาห์ที่ 1'!AH4 | E8: ='สัปดาห์ที่ 2'!AE4 | F8: ='สัปดาห์ที่ 2'!AH4 | G8: ='สัปดาห์ที่ 3'!AE4 | H8: ='สัปดาห์ที่ 3'!AH4 | I8: ='สัปดาห์ที่ 4'!AE4 | J8: ='สัปดาห์ที่ 4'!AH4 | K8: ='สัปดาห์ที่ 5'!AE4 | L8: ='สัปดาห์ที่ 5'!AH4 | M8: 0 | N8: 0 | O8: =C8+E8+G8+I8+K8 | P8: =D8+F8+H8+J8+L8
A9: 3 | B9: ='สัปดาห์ที่ 1'!AB5 | C9: ='สัปดาห์ที่ 1'!AE5 | D9: ='สัปดาห์ที่ 1'!AH5 | E9: ='สัปดาห์ที่ 2'!AE5 | F9: ='สัปดาห์ที่ 2'!AH5 | G9: ='สัปดาห์ที่ 3'!AE5 | H9: ='สัปดาห์ที่ 3'!AH5 | I9: ='สัปดาห์ที่ 4'!AE5 | J9: ='สัปดาห์ที่ 4'!AH5 | K9: ='สัปดาห์ที่ 5'!AE5 | L9: ='สัปดาห์ที่ 5'!AH5 | M9: 0 | N9: 0 | O9: =C9+E9+G9+I9+K9 | P9: =D9+F9+H9+J9+L9
A10: 4 | B10: ='สัปดาห์ที่ 1'!AB6 | C10: ='สัปดาห์ที่ 1'!AE6 | D10: ='สัปดาห์ที่ 1'!AH6 | E10: ='สัปดาห์ที่ 2'!AE6 | F10: ='สัปดาห์ที่ 2'!AH6 | G10: ='สัปดาห์ที่ 3'!AE6 | H10: ='สัปดาห์ที่ 3'!AH6 | I10: ='สัปดาห์ที่ 4'!AE6 | J10: ='สัปดาห์ที่ 4'!AH6 | K10: ='สัปดาห์ที่ 5'!AE6 | L10: ='สัปดาห์ที่ 5'!AH6 | M10: 0 | N10: 0 | O10: =C10+E10+G10+I10+K10 | P10: =D10+F10+H10+J10+L10
A11: 5 | B11: ='สัปดาห์ที่ 1'!AB7 | C11: ='สัปดาห์ที่ 1'!AE7 | D11: ='สัปดาห์ที่ 1'!AH7 | E11: ='สัปดาห์ที่ 2'!AE7 | F11: ='สัปดาห์ที่ 2'!AH7 | G11: ='สัปดาห์ที่ 3'!AE7 | H11: ='สัปดาห์ที่ 3'!AH7 | I11: ='สัปดาห์ที่ 4'!AE7 | J11: ='สัปดาห์ที่ 4'!AH7 | K11: ='สัปดาห์ที่ 5'!AE7 | L11: ='สัปดาห์ที่ 5'!AH7 | M11: 0 | N11: 0 | O11: =C11+E11+G11+I11+K11 | P11: =D11+F11+H11+J11+L11
A12: 6 | B12: ='สัปดาห์ที่ 1'!AB8 | C12: ='สัปดาห์ที่ 1'!AE8 | D12: ='สัปดาห์ที่ 1'!AH8 | E12: ='สัปดาห์ที่ 2'!AE8 | F12: ='สัปดาห์ที่ 2'!AH8 | G12: ='สัปดาห์ที่ 3'!AE8 | H12: ='สัปดาห์ที่ 3'!AH8 | I12: ='สัปดาห์ที่ 4'!AE8 | J12: ='สัปดาห์ที่ 4'!AH8 | K12: ='สัปดาห์ที่ 5'!AE8 | L12: ='สัปดาห์ที่ 5'!AH8 | M12: 0 | N12: 0 | O12: =C12+E12+G12+I12+K12 | P12: =D12+F12+H12+J12+L12
A13: 7 | B13: ='สัปดาห์ที่ 1'!AB9 | C13: ='สัปดาห์ที่ 1'!AE9 | D13: ='สัปดาห์ที่ 1'!AH9 | E13: ='สัปดาห์ที่ 2'!AE9 | F13: ='สัปดาห์ที่ 2'!AH9 | G13: ='สัปดาห์ที่ 3'!AE9 | H13: ='สัปดาห์ที่ 3'!AH9 | I13: ='สัปดาห์ที่ 4'!AE9 | J13: ='สัปดาห์ที่ 4'!AH9 | K13: ='สัปดาห์ที่ 5'!AE9 | L13: ='สัปดาห์ที่ 5'!AH9 | M13: 0 | N13: 0 | O13: =C13+E13+G13+I13+K13 | P13: =D13+F13+H13+J13+L13
A14: 8 | B14: ='สัปดาห์ที่ 1'!AB10 | C14: ='สัปดาห์ที่ 1'!AE10 | D14: ='สัปดาห์ที่ 1'!AH10 | E14: ='สัปดาห์ที่ 2'!AE10 | F14: ='สัปดาห์ที่ 2'!AH10 | G14: ='สัปดาห์ที่ 3'!AE10 | H14: ='สัปดาห์ที่ 3'!AH10 | I14: ='สัปดาห์ที่ 4'!AE10 | J14: ='สัปดาห์ที่ 4'!AH10 | K14: ='สัปดาห์ที่ 5'!AE10 | L14: ='สัปดาห์ที่ 5'!AH10 | M14: 0 | N14: 0 | O14: =C14+E14+G14+I14+K14 | P14: =D14+F14+H14+J14+L14
A15: 9 | B15: ='สัปดาห์ที่ 1'!AB11 | C15: ='สัปดาห์ที่ 1'!AE11 | D15: ='สัปดาห์ที่ 1'!AH11 | E15: ='สัปดาห์ที่ 2'!AE11 | F15: ='สัปดาห์ที่ 2'!AH11 | G15: ='สัปดาห์ที่ 3'!AE11 | H15: ='สัปดาห์ที่ 3'!AH11 | I15: ='สัปดาห์ที่ 4'!AE11 | J15: ='สัปดาห์ที่ 4'!AH11 | K15: ='สัปดาห์ที่ 5'!AE11 | L15: ='สัปดาห์ที่ 5'!AH11 | M15: 0 | N15: 0 | O15: =C15+E15+G15+I15+K15 | P15: =D15+F15+H15+J15+L15
A16: 10 | B16: ='สัปดาห์ที่ 1'!AB12 | C16: ='สัปดาห์ที่ 1'!AE12 | D16: ='สัปดาห์ที่ 1'!AH12 | E16: ='สัปดาห์ที่ 2'!AE12 | F16: ='สัปดาห์ที่ 2'!AH12 | G16: ='สัปดาห์ที่ 3'!AE12 | H16: ='สัปดาห์ที่ 3'!AH12 | I16: ='สัปดาห์ที่ 4'!AE12 | J16: ='สัปดาห์ที่ 4'!AH12 | K16: ='สัปดาห์ที่ 5'!AE12 | L16: ='สัปดาห์ที่ 5'!AH12 | M16: 0 | N16: 0 | O16: =C16+E16+G16+I16+K16 | P16: =D16+F16+H16+J16+L16
A17: 11 | B17: ='สัปดาห์ที่ 1'!AB13 | C17: ='สัปดาห์ที่ 1'!AE13 | D17: ='สัปดาห์ที่ 1'!AH13 | E17: ='สัปดาห์ที่ 2'!AE13 | F17: ='สัปดาห์ที่ 2'!AH13 | G17: ='สัปดาห์ที่ 3'!AE13 | H17: ='สัปดาห์ที่ 3'!AH13 | I17: ='สัปดาห์ที่ 4'!AE13 | J17: ='สัปดาห์ที่ 4'!AH13 | K17: ='สัปดาห์ที่ 5'!AE13 | L17: ='สัปดาห์ที่ 5'!AH13 | M17: 0 | N17: 0 | O17: =C17+E17+G17+I17+K17 | P17: =D17+F17+H17+J17+L17
A18: 12 | B18: ='สัปดาห์ที่ 1'!AB14 | C18: ='สัปดาห์ที่ 1'!AE14 | D18: ='สัปดาห์ที่ 1'!AH14 | E18: ='สัปดาห์ที่ 2'!AE14 | F18: ='สัปดาห์ที่ 2'!AH14 | G18: ='สัปดาห์ที่ 3'!AE14 | H18: ='สัปดาห์ที่ 3'!AH14 | I18: ='สัปดาห์ที่ 4'!AE14 | J18: ='สัปดาห์ที่ 4'!AH14 | K18: ='สัปดาห์ที่ 5'!AE14 | L18: ='สัปดาห์ที่ 5'!AH14 | M18: 0 | N18: 0 | O18: =C18+E18+G18+I18+K18 | P18: =D18+F18+H18+J18+L18
A19: 13 | B19: ='สัปดาห์ที่ 1'!AB15 | C19: ='สัปดาห์ที่ 1'!AE15 | D19: ='สัปดาห์ที่ 1'!AH15 | E19: ='สัปดาห์ที่ 2'!AE15 | F19: ='สัปดาห์ที่ 2'!AH15 | G19: ='สัปดาห์ที่ 3'!AE15 | H19: ='สัปดาห์ที่ 3'!AH15 | I19: ='สัปดาห์ที่ 4'!AE15 | J19: ='สัปดาห์ที่ 4'!AH15 | K19: ='สัปดาห์ที่ 5'!AE15 | L19: ='สัปดาห์ที่ 5'!AH15 | M19: 0 | N19: 0 | O19: =C19+E19+G19+I19+K19 | P19: =D19+F19+H19+J19+L19
A36: 5 | B36: ='สัปดาห์ที่ 1'!AB27 | C36: ='สัปดาห์ที่ 1'!AE27 | D36: ='สัปดาห์ที่ 1'!AH27 | E36: ='สัปดาห์ที่ 2'!AE27 | F36: ='สัปดาห์ที่ 2'!AH27 | G36: ='สัปดาห์ที่ 3'!AE27 | H36: ='สัปดาห์ที่ 3'!AH27 | I36: ='สัปดาห์ที่ 4'!AE27 | J36: ='สัปดาห์ที่ 4'!AH27 | K36: ='สัปดาห์ที่ 5'!AE27 | L36: ='สัปดาห์ที่ 5'!AH27 | M36: 0 | N36: 0 | O36: =C36+E36+G36+I36+K36+M36 | P36: =D36+F36+H36+J36+L36+N36
A37: 6 | K37: 0 | L37: 0 | M37: 0 | N37: 0
A38: รวมเงินครูพิเศษ | P38: =SUM(P32:P37)
D40: แผนกยานยนต์ไฟฟ้า
D42: ครูประจำ
A43: ลำดับ | B43: ชื่อ-สกุล | C43: 1 | E43: 2 | G43: 3 | I43: 4 | K43: 5 | M43: 6 | O43: รวม / ชม. | P43: รวม
C44: ชม/ส | D44: เงิน | E44: ชม/ส | F44: เงิน | G44: ชม/ส | H44: เงิน | I44: ชม/ส | J44: เงิน | K44: ชม/ส | L44: เงิน | M44: ชม/ส | N44: เงิน
A45: 1 | B45: ='สัปดาห์ที่ 1'!AB28 | C45: =#REF! | D45: =#REF! | E45: =#REF! | F45: =#REF! | G45: =#REF! | H45: =#REF! | I45: =#REF! | J45: =#REF! | M45: 0 | N45: 0 | O45: =C45+E45+G45+I45+K45+M45 | P45: =D45+F45+H45+J45+L45+N45
A46: 2 | B46: ='สัปดาห์ที่ 1'!AB29 | C46: =#REF! | D46: =#REF! | E46: =#REF! | F46: =#REF! | G46: =#REF! | H46: =#REF! | I46: =#REF! | J46: =#REF! | M46: 0 | N46: 0 | O46: =C46+E46+G46+I46+K46 | P46: =D46+F46+H46+J46+L46
A47: 3 | B47: ='สัปดาห์ที่ 1'!AB30 | C47: =#REF! | D47: =#REF! | E47: =#REF! | F47: =#REF! | G47: =#REF! | H47: =#REF! | I47: =#REF! | J47: =#REF! | M47: 0 | N47: 0 | O47: =C47+E47+G47+I47+K47 | P47: =D47+F47+H47+J47+L47
A48: รวมเงินครูประจำ | P48: =SUM(P45:P47)
D49: ครูพิเศษ
A50: ลำดับ | B50: ชื่อ-สกุล | C50: 1 | E50: 2 | G50: 3 | I50: 4 | K50: 5 | M50: 6 | O50: รวม / ชม. | P50: รวม
C51: ชม/ส | D51: เงิน | E51: ชม/ส | F51: เงิน | G51: ชม/ส | H51: เงิน | I51: ชม/ส | J51: เงิน | K51: ชม/ส | L51: เงิน | M51: ชม/ส | N51: เงิน
A52: 1 | O52: =C52+E52+G52+I52+K52 | P52: =D52+F52+H52+J52+L52
A53: 2 | O53: =C53+E53+G53+I53+K53 | P53: =D53+F53+H53+J53+L53
A54: รวมเงินครูพิเศษ | P54: =SUM(P52:P53)
A56: ยอดเงินรายรับ ÷ ยอดคน | D56: =P27+P38+P48+P54 | E56: ÷ | F56: 28 | H56: = | J56: =D56/F56
A57: หักเข้ากองกลาง (4 ส.x100) x 28 คน | D57: 400 | E57: x | F57: 28 | H57: = | J57: =D57*F57
A59: เงินที่ได้รับ คนละ | D59: =J56 | E59: - | F59: =D57 | J59: = | K59: =J56-D57
A60: ปัดให้ลงตัว | D60: =K59 | E60: + | F60: 46 | J60: = | K60: =D60+F60
A62: เงินกองกลาง | J62: = | K62: =J57
A63: เงินเข้ากองกลางคงเหลือ | D63: =J57 | E63: - | F63: =F60*F56 | J63: = | K63: =D63-F63
...

Sheet งบหน้ารวมครู
A1: หลักฐานการเบิกจ่ายเงินค่าสอนพิเศษและค่าสอนเกินภาระงานสอนในสถานศึกษา
B2: ส่วนราชการ วิทยาลัยเทคนิคนครสวรรค์ | H2: ประจำเดือน | I2: 14 กันยายน 2569 - 16 ตุลาคม 2569
G4: ระดับการสอน | I4: จำนวนหน่วย | J4: จำนวนเงิน | K4: ลายมือชื่อผู้รับเงิน | L4: วัน/เดือน/ปี | M4: หมายเหตุ
A5: ลำดับที่ | B5: ชื่อ - นามสกุล | F5: ตำแหน่ง | G5: มัธยมศึกษาตอนต้น | H5: สูงกว่า | I5: ชั่วโมงที่ทำการสอน
F6: ผู้ทำการสอน | G6: หรือมัธยมศึกษาตอนปลาย | H6: มัธยมศึกษาตอนปลาย | I6: พิเศษและสอนเกิน | L6: ที่รับเงิน
G7: หรือเทียบเท่า | H7: หรือเทียบเท่า | I7: ภาระงานสอน | O7: =#REF!
A8: 1 | B8: =ตารางแจงเงินรายบุคคล!B7 | F8: ครู | G8: ü | I8: =ตารางแจงเงินรายบุคคล!O7 | J8: =ตารางแจงเงินรายบุคคล!P7 | O8: =#REF!
A9: 2 | B9: =ตารางแจงเงินรายบุคคล!B8 | F9: ครู | G9: ü | I9: =ตารางแจงเงินรายบุคคล!O8 | J9: =ตารางแจงเงินรายบุคคล!P8 | O9: =#REF!
A10: 3 | B10: =ตารางแจงเงินรายบุคคล!B9 | F10: ครู | G10: ü | I10: =ตารางแจงเงินรายบุคคล!O9 | J10: =ตารางแจงเงินรายบุคคล!P9 | O10: =#REF!
A11: 4 | B11: =ตารางแจงเงินรายบุคคล!B10 | F11: ครู | G11: ü | I11: =ตารางแจงเงินรายบุคคล!O10 | J11: =ตารางแจงเงินรายบุคคล!P10 | O11: =#REF!
A12: 5 | B12: =ตารางแจงเงินรายบุคคล!B11 | F12: ครู | G12: ü | I12: =ตารางแจงเงินรายบุคคล!O11 | J12: =ตารางแจงเงินรายบุคคล!P11 | O12: =#REF!
A13: 6 | B13: =ตารางแจงเงินรายบุคคล!B12 | F13: ครู | G13: ü | I13: =ตารางแจงเงินรายบุคคล!O12 | J13: =ตารางแจงเงินรายบุคคล!P12 | O13: =#REF!
A14: 7 | B14: =ตารางแจงเงินรายบุคคล!B13 | F14: ครู | G14: ü | I14: =ตารางแจงเงินรายบุคคล!O13 | J14: =ตารางแจงเงินรายบุคคล!P13 | O14: =#REF!
A15: 8 | B15: =ตารางแจงเงินรายบุคคล!B14 | F15: ครู | G15: ü | I15: =ตารางแจงเงินรายบุคคล!O14 | J15: =ตารางแจงเงินรายบุคคล!P14 | O15: =#REF!
C16: ย/ป | E16: รวมจำนวนเงิน | G16: =B19 | J16: =SUM(J8:J15) | O16: =#REF!
F17: ผู้ทำ | J17: ผู้จ่ายเงิน | O17: =#REF!
A18: รวมจำนวนเงินค่าสอนพิเศษทั้งสิ้น | C18: =J16 | D18: บาท | F18: ลงชื่อ......................................... | J18: ลงชื่อ......................................... | O18: =#REF!
A19: ( | B19: =BAHTTEXT(C18) | E19: ) | F19: (นายชำนาญ แก้วจงประสิทธิ์) | J19: (นางวีณา กฐินทอง ) | O19: =#REF!
F20: ตำแหน่งครู หัวหน้าแผนกวิชาช่างยนต์ | J20: ตำแหน่ง หัวหน้างานการเงิน | O20: =#REF!
F21: วันที่.......เดือน..........................พ.ศ.............. | J21: วันที่........เดือน...............พ.ศ...........
A22: ผู้รับรอง | F22: ผู้เห็นชอบ | J22: ผู้อนุมัติ | O22: =O7+O8+O9+O10+O11+O12+O13+O14+O15+O16+O17+O18+O19+O20
A23: ลงชื่อ........................................................................... | F23: ลงชื่อ............................................................... | J23: ลงชื่อ...................................................................
B24: (นายฉัตรชัย งาหอม) | G24: (นายปรีชา โพธิ์เกิด) | K24: (นายปริวิชญ์ ไชยประเสริฐ)
A25: ตำแหน่ง รองผู้อำนวยการฝ่ายวิชาการ | F25: ตำแหน่ง รองผู้อำนวยการฝ่ายบริหารทรัพยากร | J25: ตำแหน่ง ผู้อำนวยการวิทยาลัยเทคนิคนครสวรรค์
A26: วันที่..................เดือน..........................พ.ศ................ | F26: วันที่.............เดือน.......................พ.ศ............. | J26: วันที่...........เดือน...................พ.ศ..........
A27: หลักฐานการเบิกจ่ายเงินค่าสอนพิเศษและค่าสอนเกินภาระงานสอนในสถานศึกษา
B28: ส่วนราชการ วิทยาลัยเทคนิคนครสวรรค์ | H28: ประจำเดือน | I28: =I2
G30: ระดับการสอน | I30: จำนวนหน่วย | J30: จำนวนเงิน | M30: หมายเหตุ
A31: ลำดับที่ | B31: ชื่อ - นามสกุล | F31: ตำแหน่ง | G31: มัธยมศึกษาตอนต้น | H31: สูงกว่า | I31: ชั่วโมงที่ทำการสอน | K31: ลายมือชื่อ | L31: วัน/เดือน/ปี
F32: ผู้ทำการสอน | G32: หรือมัธยมศึกษาตอนปลาย | H32: มัธยมศึกษาตอนปลาย | I32: พิเศษและสอนเกิน | K32: ผู้รับเงิน | L32: ที่รับเงิน
G33: หรือเทียบเท่า | H33: หรือเทียบเท่า | I33: ภาระงานสอน
B34: ย/ม | J34: =J16
A35: 9 | B35: =ตารางแจงเงินรายบุคคล!B15 | F35: ครู | G35: ü | I35: =ตารางแจงเงินรายบุคคล!O15 | J35: =ตารางแจงเงินรายบุคคล!P15
A36: 10 | B36: =ตารางแจงเงินรายบุคคล!B16 | F36: ครู | G36: ü | I36: =ตารางแจงเงินรายบุคคล!O16 | J36: =ตารางแจงเงินรายบุคคล!P16
A37: 11 | B37: =ตารางแจงเงินรายบุคคล!B17 | F37: ครู | G37: ü | I37: =ตารางแจงเงินรายบุคคล!O17 | J37: =ตารางแจงเงินรายบุคคล!P17
A38: 12 | B38: =ตารางแจงเงินรายบุคคล!B18 | F38: ครู | G38: ü | I38: =ตารางแจงเงินรายบุคคล!O18 | J38: =ตารางแจงเงินรายบุคคล!P18
A39: 13 | B39: =ตารางแจงเงินรายบุคคล!B19 | F39: พนักงานราชการ | G39: ü | I39: =ตารางแจงเงินรายบุคคล!O19 | J39: =ตารางแจงเงินรายบุคคล!P19
C42: ย/ป | E42: รวมจำนวนเงิน | G42: =B45 | J42: =SUM(J34:J41)
F43: ผู้ทำ | J43: ผู้จ่ายเงิน
A44: รวมจำนวนเงินค่าสอนพิเศษทั้งสิ้น | C44: =J42 | D44: บาท | F44: ลงชื่อ......................................... | J44: ลงชื่อ.........................................
...

Sheet สรุปลา 
