Workbook

Sheet สัปดาห์ที่ 1
A1: ใบเบิกจ่ายเงินค่าสอนพิเศษและค่าสอนเกินภาระงานสอนในสถานศึกษา
A2: แผนกวิชายานยนต์ไฟฟ้า | Z2: ลำดับ | AB2: รายชื่อ | AE2: รวม ชม./ ส. | AH2: รวม ค่าสอน / สัปดาห์
A3: ระหว่างวันที่ | D3: 27 | E3: เดือน | F3: พฤศจิกายน | H3: พ.ศ. 2566 | I3: ถึง วันที่ | J3: 1 | K3: เดือน | L3: ธันวาคม | N3: พ.ศ. 2566 | Z3: 1 | AB3: นายอาทิตย์ แก้วแดง | AC3: นายอาทิตย์ แก้วแดง | AD3: นายอาทิตย์ แก้วแดง | AE3: =H36 -> 12 | AH3: =P36 -> 3240
G4: ü | H4: ครู | I4: หน้าที่พิเศษ | J4: หัวหน้าแผนกยานยนต์ไฟฟ้า | Z4: 2 | AE4: =H82 -> 0 | AH4: =P82 -> 0
A5: ที่ | B5: ชื่อ-สกุล | E5: ตำแหน่ง | F5: ระยะเวลาที่สอน | H5: รหัสวิชา | I5: ชั้น,แผนก,ห้อง | J5: เวลาสอน | L5: ปวช.(คาบ) | N5: เงิน | O5: ยอดเงิน | P5: ปวส.(คาบ) | R5: เงิน | S5: ยอดเงิน | Z5: 3 | AE5: =H128 -> 0 | AH5: =P128 -> 0
F6: ส. | G6: วดป. | L6: ใน | M6: นอก | N6: ต่อ ชม. | O6: (บาท) | P6: ใน | Q6: นอก | R6: ต่อ ชม. | S6: (บาท) | Z6: 4 | AC6: นายธนิต กฐินทอง | AD6: นายธนิต กฐินทอง | AE6: =H174 -> 0 | AH6: =P174 -> 0
A7: 1 | B7: =AB3 -> นายอาทิตย์ แก้วแดง | E7: ครู | F7: 7 | G7: จันทร์ | H7: 30101-2607 | I7: ปวส.2/5 สยฟ. (ม.6) | J7: 08.10-12.10 | O7: =M7*N7 -> 0 | Q7: 4 | R7: 270 | S7: =Q7*R7 -> 1080 | Z7: 5 | AC7: นายสุริยา คำอุดม | AD7: นายสุริยา คำอุดม | AE7: =H220 -> 0 | AH7: =P220 -> 0
G8: 27 พ.ย.66 | H8: 30143-2005 | I8: ปวส.1/2 สยฟ. (ทวิ) | J8: 14.10-19.10 | O8: =M8*N8 -> 0 | P8: 5 | S8: =Q8*R8 -> 0 | Z8: 6 | AC8: นายดำเนิน สุขขี | AD8: นายดำเนิน สุขขี | AE8: =H266 -> 0 | AH8: =P266 -> 0
O9: =M9*N9 -> 0 | S9: =Q9*R9 -> 0 | T9: สอน ป.ตรี | Z9: 7 | AC9: นายอาทิตย์ แก้วแดง | AD9: นายอาทิตย์ แก้วแดง | AE9: =H312 -> 0 | AH9: =P312 -> 0
O10: =M10*N10 -> 0 | S10: =Q10*R10 -> 0 | U10: 19.10-20.10 | Z10: 8 | AE10: =H358 -> 0 | AH10: =P358 -> 0
O11: =M11*N11 -> 0 | S11: =Q11*R11 -> 0 | Z11: 9 | AE11: =H404 -> 0 | AH11: =P404 -> 0
G12: อังคาร | O12: =M12*N12 -> 0 | S12: =Q12*R12 -> 0 | Z12: 10 | AE12: =H450 -> 0 | AH12: =P450 -> 0
G13: 28 พ.ย.66 | O13: =M13*N13 -> 0 | S13: =Q13*R13 -> 0 | Z13: 11 | AE13: =H496 -> 0 | AH13: =P496 -> 0
O14: =M14*N14 -> 0 | S14: =Q14*R14 -> 0 | Z14: 12 | AE14: =H542 -> 0 | AH14: =P542 -> 0
O15: =M15*N15 -> 0 | S15: =Q15*R15 -> 0 | Z15: 13 | AE15: =H588 -> 0 | AH15: =P588 -> 0
O16: =M16*N16 -> 0 | S16: =Q16*R16 -> 0 | Z16: 14 | AE16: =H634 -> 0 | AH16: =P634 -> 0
G17: พุธ | H17: 30143-2004 | I17: ปวส.1/1 สยฟ. (ทวิ) | J17: 08.10-12.10 | O17: =M17*N17 -> 0 | Q17: 4 | R17: 270 | S17: =Q17*R17 -> 1080 | Z17: 15 | AE17: =H680 -> 0 | AH17: =P680 -> 0
G18: 29 พ.ย.66 | H18: 30143-2004 | I18: ปวส.1/1 สยฟ. (ทวิ) | J18: 13.10-14.10 | O18: =M18*N18 -> 0 | P18: 1 | S18: =Q18*R18 -> 0 | Z18: 16 | AE18: =H726 -> 0 | AH18: =P726 -> 0
H19: 30143-2004 | I19: ปวส.1/2 สยฟ. (ทวิ) | J19: 14.10-19.10 | O19: =M19*N19 -> 0 | P19: 5 | S19: =Q19*R19 -> 0 | T19: สอน ป.ตรี | Z19: 17 | AE19: =H772 -> 0 | AH19: =P772 -> 0
O20: =M20*N20 -> 0 | S20: =Q20*R20 -> 0 | U20: 19.10-20.10 | Z20: 18 | AE20: =H818 -> 0 | AH20: =P818 -> 0
O21: =M21*N21 -> 0 | S21: =Q21*R21 -> 0 | Z21: 19 | AE21: =H864 -> 0 | AH21: =P864 -> 0
G22: พฤหัส | H22: 30101-2607 | I22: ปวส. 2/6 สยฟ. (ม.6) | J22: 08.10-12.10 | O22: =M22*N22 -> 0 | Q22: 4 | R22: 270 | S22: =Q22*R22 -> 1080 | Z22: 20 | AE22: =H910 -> 0 | AH22: =P910 -> 0
G23: 30 พ.ย.66 | H23: 30000-2002 | I23: ปวส.1/1,2 สยฟ. (ทวิ) | J23: 13.10-15.10 | O23: =M23*N23 -> 0 | P23: 2 | S23: =Q23*R23 -> 0 | Z23: 21 | AE23: =H956 -> 0 | AH23: =P956 -> 0
O24: =M24*N24 -> 0 | S24: =Q24*R24 -> 0 | U24: PLC | Z24: 22 | AE24: =H1002 -> 0 | AH24: =P1002 -> 0
O25: =M25*N25 -> 0 | S25: =Q25*R25 -> 0 | U25: 17.10-19.10 | Z25: 23 | AE25: =H1048 -> 0 | AH25: =P1048 -> 0
O26: =M26*N26 -> 0 | S26: =Q26*R26 -> 0 | Z26: 24 | AE26: =H1094 -> 0 | AH26: =P1094 -> 0
G27: ศุกร์ | H27: 30143-2005 | I27: ปวส.1/1 สยฟ. (ทวิ) | J27: 08.10-12.10 | O27: =M27*N27 -> 0 | P27: 4 | S27: =Q27*R27 -> 0 | Z27: 25 | AE27: =H1140 -> 0 | AH27: =P1140 -> 0
G28: 1 ธ.ค.66 | H28: 30143-2005 | I28: ปวส.1/1 สยฟ. (ทวิ) | J28: 13.10-14.10 | O28: =M28*N28 -> 0 | P28: 1 | S28: =Q28*R28 -> 0 | Z28: 26 | AC28: นายชินวัฒน์ พิลึก | AD28: นายชินวัฒน์ พิลึก | AE28: =H1186 -> 0 | AH28: =P1186 -> 0
O29: =M29*N29 -> 0 | S29: =Q29*R29 -> 0 | U29: เบิก ธุรการ | Z29: 27 | AC29: นายชินวัฒน์ พิลึก | AD29: นายชินวัฒน์ พิลึก | AE29: =H1232 -> 0 | AH29: =P1232 -> 0
O30: =M30*N30 -> 0 | S30: =Q30*R30 -> 0 | U30: 16.10-19.10
O31: =M31*N31 -> 0 | S31: =Q31*R31 -> 0
G32: รวมขั่วโมงที่สอนแยก ภาระงาน/ เกินภาระงาน | L32: =SUM(L7:L31) -> 0 | M32: =SUM(M7:M31) -> 0 | P32: =SUM(P7:P31) -> 18 | Q32: =SUM(Q7:Q31) -> 12
G33: รวมจำนวนชั่วโมงสอนคาบต่อสับดาห์ | L33: =L32+M32 -> 0 | P33: =P32+Q32 -> 30
G34: จำนวนชั่วโมงสอนตามภาระงานสอน | L34: 0 | P34: 10
G35: จำนวนชั่วโมงบิกเกินภาระงานสอน/ค่าสอน | L35: 0 | M35: =SUM(M7:M31) -> 0 | O35: =SUM(O7:O31) -> 0 | P35: 0 | Q35: =SUM(Q7:Q31) -> 12 | S35: =SUM(S7:S31) -> 3240
A36: รวมจำนวนหน่วยชั่วโมงที่ขอเบิกค่าสอน …. | H36: =M35+Q35 -> 12 | I36: ….ชั่วโมง | K36: ยอดเงินรวม | P36: =S35+O35 -> 3240 | S36: ..บาท
A37: ผู้ขอเบิก | H37: ผู้รับรอง | M37: ผู้ตรวจ
A38: ลงชื่อ…………………………………………… | H38: ลงชื่อ…………………………………………… | M38: ลงชื่อ……………………………………………
A39: ( | B39: =B7 -> นายอาทิตย์ แก้วแดง | G39: ) | H39: ( | I39: นายอาทิตย์ แก้วแดง | L39: ) | M39: ( | O39: นายทศวรรษ คำสม | S39: )
A40: ตำแหน่ง ครู | H40: ตำแหน่ง หัวหน้าแผนก | M40: ตำแหน่ง ผู้ตรวจสอบ
...

Sheet สัปดาห์ที่ 2
A1: ใบเบิกจ่ายเงินค่าสอนพิเศษและค่าสอนเกินภาระงานสอนในสถานศึกษา
A2: แผนกวิชายานยนต์ไฟฟ้า | Z2: ลำดับ | AB2: รายชื่อ | AE2: รวม ชม./ ส. | AH2: รวม ค่าสอน / สัปดาห์
A3: ระหว่างวันที่ | D3: 4 | E3: เดือน | F3: ธันวาคม | H3: พ.ศ. 2566 | I3: ถึง วันที่ | J3: 8 | K3: เดือน | L3: ธันวาคม | N3: พ.ศ. 2566 | Z3: 1 | AB3: นายอาทิตย์ แก้วแดง | AC3: นายอาทิตย์ แก้วแดง | AD3: นายอาทิตย์ แก้วแดง | AE3: =H36 -> 12 | AH3: =P36 -> 3240
G4: ü | H4: ครู | I4: หน้าที่พิเศษ | J4: หัวหน้าแผนกยานยนต์ไฟฟ้า | Z4: 2 | AB4: นางสาวปาจารีย์ กฐินทอง | AE4: =H82 -> 7 | AH4: =P82 -> 1400
A5: ที่ | B5: ชื่อ-สกุล | E5: ตำแหน่ง | F5: ระยะเวลาที่สอน | H5: รหัสวิชา | I5: ชั้น,แผนก,ห้อง | J5: เวลาสอน | L5: ปวช.(คาบ) | N5: เงิน | O5: ยอดเงิน | P5: ปวส.(คาบ) | R5: เงิน | S5: ยอดเงิน | Z5: 3 | AE5: =H128 -> 0 | AH5: =P128 -> 0
F6: ส. | G6: วดป. | L6: ใน | M6: นอก | N6: ต่อ ชม. | O6: (บาท) | P6: ใน | Q6: นอก | R6: ต่อ ชม. | S6: (บาท) | Z6: 4 | AC6: นายธนิต กฐินทอง | AD6: นายธนิต กฐินทอง | AE6: =H174 -> 0 | AH6: =P174 -> 0
A7: 1 | B7: =AB3 -> นายอาทิตย์ แก้วแดง | E7: ครู | F7: 8 | G7: จันทร์ | H7: 30101-2607 | I7: ปวส.2/5 สยฟ. (ม.6) | J7: 08.10-12.10 | O7: =M7*N7 -> 0 | Q7: 4 | R7: 270 | S7: =Q7*R7 -> 1080 | Z7: 5 | AC7: นายสุริยา คำอุดม | AD7: นายสุริยา คำอุดม | AE7: =H220 -> 0 | AH7: =P220 -> 0
G8: 4 ธ.ค.66 | H8: 30143-2005 | I8: ปวส.1/2 สยฟ. (ทวิ) | J8: 14.10-19.10 | O8: =M8*N8 -> 0 | P8: 5 | S8: =Q8*R8 -> 0 | Z8: 6 | AC8: นายดำเนิน สุขขี | AD8: นายดำเนิน สุขขี | AE8: =H266 -> 0 | AH8: =P266 -> 0
O9: =M9*N9 -> 0 | S9: =Q9*R9 -> 0 | T9: สอน ป.ตรี | Z9: 7 | AC9: นายอาทิตย์ แก้วแดง | AD9: นายอาทิตย์ แก้วแดง | AE9: =H312 -> 0 | AH9: =P312 -> 0
O10: =M10*N10 -> 0 | S10: =Q10*R10 -> 0 | U10: 19.10-20.10 | Z10: 8 | AE10: =H358 -> 0 | AH10: =P358 -> 0
O11: =M11*N11 -> 0 | S11: =Q11*R11 -> 0 | Z11: 9 | AE11: =H404 -> 0 | AH11: =P404 -> 0
G12: อังคาร | H12: หยุด | O12: =M12*N12 -> 0 | S12: =Q12*R12 -> 0 | Z12: 10 | AE12: =H450 -> 0 | AH12: =P450 -> 0
G13: 5 ธ.ค.66 | O13: =M13*N13 -> 0 | S13: =Q13*R13 -> 0 | Z13: 11 | AE13: =H496 -> 0 | AH13: =P496 -> 0
O14: =M14*N14 -> 0 | S14: =Q14*R14 -> 0 | Z14: 12 | AE14: =H542 -> 0 | AH14: =P542 -> 0
O15: =M15*N15 -> 0 | S15: =Q15*R15 -> 0 | Z15: 13 | AE15: =H588 -> 0 | AH15: =P588 -> 0
O16: =M16*N16 -> 0 | S16: =Q16*R16 -> 0 | Z16: 14 | AE16: =H634 -> 0 | AH16: =P634 -> 0
G17: พุธ | H17: 30143-2004 | I17: ปวส.1/1 สยฟ. (ทวิ) | J17: 08.10-12.10 | O17: =M17*N17 -> 0 | Q17: 4 | R17: 270 | S17: =Q17*R17 -> 1080 | Z17: 15 | AE17: =H680 -> 0 | AH17: =P680 -> 0
G18: 6 ธ.ค.66 | H18: 30143-2004 | I18: ปวส.1/1 สยฟ. (ทวิ) | J18: 13.10-14.10 | O18: =M18*N18 -> 0 | P18: 1 | S18: =Q18*R18 -> 0 | Z18: 16 | AE18: =H726 -> 0 | AH18: =P726 -> 0
H19: 30143-2004 | I19: ปวส.1/2 สยฟ. (ทวิ) | J19: 14.10-19.10 | O19: =M19*N19 -> 0 | P19: 5 | S19: =Q19*R19 -> 0 | T19: สอน ป.ตรี | Z19: 17 | AE19: =H772 -> 0 | AH19: =P772 -> 0
O20: =M20*N20 -> 0 | S20: =Q20*R20 -> 0 | U20: 19.10-20.10 | Z20: 18 | AE20: =H818 -> 0 | AH20: =P818 -> 0
O21: =M21*N21 -> 0 | S21: =Q21*R21 -> 0 | Z21: 19 | AE21: =H864 -> 0 | AH21: =P864 -> 0
G22: พฤหัส | H22: 30101-2607 | I22: ปวส. 2/6 สยฟ. (ม.6) | J22: 08.10-12.10 | O22: =M22*N22 -> 0 | Q22: 4 | R22: 270 | S22: =Q22*R22 -> 1080 | Z22: 20 | AE22: =H910 -> 0 | AH22: =P910 -> 0
G23: 7 ธ.ค.66 | H23: 30000-2002 | I23: ปวส.1/1,2 สยฟ. (ทวิ) | J23: 13.10-15.10 | O23: =M23*N23 -> 0 | P23: 2 | S23: =Q23*R23 -> 0 | Z23: 21 | AE23: =H956 -> 0 | AH23: =P956 -> 0
O24: =M24*N24 -> 0 | S24: =Q24*R24 -> 0 | U24: PLC | Z24: 22 | AE24: =H1002 -> 0 | AH24: =P1002 -> 0
O25: =M25*N25 -> 0 | S25: =Q25*R25 -> 0 | U25: 17.10-19.10 | Z25: 23 | AE25: =H1048 -> 0 | AH25: =P1048 -> 0
O26: =M26*N26 -> 0 | S26: =Q26*R26 -> 0 | Z26: 24 | AE26: =H1094 -> 0 | AH26: =P1094 -> 0
G27: ศุกร์ | H27: 30143-2005 | I27: ปวส.1/1 สยฟ. (ทวิ) | J27: 08.10-12.10 | O27: =M27*N27 -> 0 | P27: 4 | S27: =Q27*R27 -> 0 | Z27: 25 | AE27: =H1140 -> 0 | AH27: =P1140 -> 0
G28: 8 ธ.ค.66 | H28: 30143-2005 | I28: ปวส.1/1 สยฟ. (ทวิ) | J28: 13.10-14.10 | O28: =M28*N28 -> 0 | P28: 1 | S28: =Q28*R28 -> 0 | Z28: 26 | AC28: นายชินวัฒน์ พิลึก | AD28: นายชินวัฒน์ พิลึก | AE28: =H1186 -> 0 | AH28: =P1186 -> 0
O29: =M29*N29 -> 0 | S29: =Q29*R29 -> 0 | U29: เบิก ธุรการ | Z29: 27 | AC29: นายชินวัฒน์ พิลึก | AD29: นายชินวัฒน์ พิลึก | AE29: =H1232 -> 0 | AH29: =P1232 -> 0
O30: =M30*N30 -> 0 | S30: =Q30*R30 -> 0 | U30: 16.10-19.10
O31: =M31*N31 -> 0 | S31: =Q31*R31 -> 0
G32: รวมขั่วโมงที่สอนแยก ภาระงาน/ เกินภาระงาน | L32: =SUM(L7:L31) -> 0 | M32: =SUM(M7:M31) -> 0 | P32: =SUM(P7:P31) -> 18 | Q32: =SUM(Q7:Q31) -> 12
G33: รวมจำนวนชั่วโมงสอนคาบต่อสับดาห์ | L33: =L32+M32 -> 0 | P33: =P32+Q32 -> 30
G34: จำนวนชั่วโมงสอนตามภาระงานสอน | L34: 0 | P34: 10
G35: จำนวนชั่วโมงบิกเกินภาระงานสอน/ค่าสอน | L35: 0 | M35: =SUM(M7:M31) -> 0 | O35: =SUM(O7:O31) -> 0 | P35: 0 | Q35: =SUM(Q7:Q31) -> 12 | S35: =SUM(S7:S31) -> 3240
A36: รวมจำนวนหน่วยชั่วโมงที่ขอเบิกค่าสอน …. | H36: =M35+Q35 -> 12 | I36: ….ชั่วโมง | K36: ยอดเงินรวม | P36: =S35+O35 -> 3240 | S36: ..บาท
A37: ผู้ขอเบิก | H37: ผู้รับรอง | M37: ผู้ตรวจ
A38: ลงชื่อ…………………………………………… | H38: ลงชื่อ…………………………………………… | M38: ลงชื่อ……………………………………………
A39: ( | B39: =B7 -> นายอาทิตย์ แก้วแดง | G39: ) | H39: ( | I39: นายอาทิตย์ แก้วแดง | L39: ) | M39: ( | O39: นายทศวรรษ คำสม | S39: )
A40: ตำแหน่ง ครู | H40: ตำแหน่ง หัวหน้าแผนก | M40: ตำแหน่ง ผู้ตรวจสอบ
...

Sheet สัปดาห์ที่ 3
A1: ใบเบิกจ่ายเงินค่าสอนพิเศษและค่าสอนเกินภาระงานสอนในสถานศึกษา
A2: แผนกวิชายานยนต์ไฟฟ้า | Z2: ลำดับ | AB2: รายชื่อ | AE2: รวม ชม./ ส. | AH2: รวม ค่าสอน / สัปดาห์
A3: ระหว่างวันที่ | D3: 18 | E3: เดือน | F3: ธันวาคม | H3: พ.ศ. 2566 | I3: ถึง วันที่ | J3: 22 | K3: เดือน | L3: ธันวาคม | N3: พ.ศ. 2566 | Z3: 1 | AB3: นายอาทิตย์ แก้วแดง | AC3: นายอาทิตย์ แก้วแดง | AD3: นายอาทิตย์ แก้วแดง | AE3: =H36 -> 12 | AH3: =P36 -> 3240
G4: ü | H4: ครู | I4: หน้าที่พิเศษ | J4: หัวหน้าแผนกยานยนต์ไฟฟ้า | Z4: 2 | AB4: นางสาวปาจารีย์ กฐินทอง | AE4: =H82 -> 12 | AH4: =P82 -> 2400
A5: ที่ | B5: ชื่อ-สกุล | E5: ตำแหน่ง | F5: ระยะเวลาที่สอน | H5: รหัสวิชา | I5: ชั้น,แผนก,ห้อง | J5: เวลาสอน | L5: ปวช.(คาบ) | N5: เงิน | O5: ยอดเงิน | P5: ปวส.(คาบ) | R5: เงิน | S5: ยอดเงิน | Z5: 3 | AE5: =H128 -> 0 | AH5: =P128 -> 0
F6: ส. | G6: วดป. | L6: ใน | M6: นอก | N6: ต่อ ชม. | O6: (บาท) | P6: ใน | Q6: นอก | R6: ต่อ ชม. | S6: (บาท) | Z6: 4 | AC6: นายธนิต กฐินทอง | AD6: นายธนิต กฐินทอง | AE6: =H174 -> 0 | AH6: =P174 -> 0
A7: 1 | B7: =AB3 -> นายอาทิตย์ แก้วแดง | E7: ครู | F7: 10 | G7: จันทร์ | H7: 30101-2607 | I7: ปวส.2/5 สยฟ. (ม.6) | J7: 08.10-12.10 | O7: =M7*N7 -> 0 | Q7: 4 | R7: 270 | S7: =Q7*R7 -> 1080 | Z7: 5 | AC7: นายสุริยา คำอุดม | AD7: นายสุริยา คำอุดม | AE7: =H220 -> 0 | AH7: =P220 -> 0
G8: 18 ธ.ค.66 | H8: 30143-2005 | I8: ปวส.1/2 สยฟ. (ทวิ) | J8: 14.10-19.10 | O8: =M8*N8 -> 0 | P8: 5 | S8: =Q8*R8 -> 0 | Z8: 6 | AC8: นายดำเนิน สุขขี | AD8: นายดำเนิน สุขขี | AE8: =H266 -> 0 | AH8: =P266 -> 0
O9: =M9*N9 -> 0 | S9: =Q9*R9 -> 0 | T9: สอน ป.ตรี | Z9: 7 | AC9: นายอาทิตย์ แก้วแดง | AD9: นายอาทิตย์ แก้วแดง | AE9: =H312 -> 0 | AH9: =P312 -> 0
O10: =M10*N10 -> 0 | S10: =Q10*R10 -> 0 | U10: 19.10-20.10 | Z10: 8 | AE10: =H358 -> 0 | AH10: =P358 -> 0
O11: =M11*N11 -> 0 | S11: =Q11*R11 -> 0 | Z11: 9 | AE11: =H404 -> 0 | AH11: =P404 -> 0
G12: อังคาร | O12: =M12*N12 -> 0 | S12: =Q12*R12 -> 0 | Z12: 10 | AE12: =H450 -> 0 | AH12: =P450 -> 0
G13: 19 ธ.ค.66 | O13: =M13*N13 -> 0 | S13: =Q13*R13 -> 0 | Z13: 11 | AE13: =H496 -> 0 | AH13: =P496 -> 0
O14: =M14*N14 -> 0 | S14: =Q14*R14 -> 0 | Z14: 12 | AE14: =H542 -> 0 | AH14: =P542 -> 0
O15: =M15*N15 -> 0 | S15: =Q15*R15 -> 0 | Z15: 13 | AE15: =H588 -> 0 | AH15: =P588 -> 0
O16: =M16*N16 -> 0 | S16: =Q16*R16 -> 0 | Z16: 14 | AE16: =H634 -> 0 | AH16: =P634 -> 0
G17: พุธ | H17: 30143-2004 | I17: ปวส.1/1 สยฟ. (ทวิ) | J17: 08.10-12.10 | O17: =M17*N17 -> 0 | Q17: 4 | R17: 270 | S17: =Q17*R17 -> 1080 | Z17: 15 | AE17: =H680 -> 0 | AH17: =P680 -> 0
G18: 20 ธ.ค.66 | H18: 30143-2004 | I18: ปวส.1/1 สยฟ. (ทวิ) | J18: 13.10-14.10 | O18: =M18*N18 -> 0 | P18: 1 | S18: =Q18*R18 -> 0 | Z18: 16 | AE18: =H726 -> 0 | AH18: =P726 -> 0
H19: 30143-2004 | I19: ปวส.1/2 สยฟ. (ทวิ) | J19: 14.10-19.10 | O19: =M19*N19 -> 0 | P19: 5 | S19: =Q19*R19 -> 0 | T19: สอน ป.ตรี | Z19: 17 | AE19: =H772 -> 0 | AH19: =P772 -> 0
O20: =M20*N20 -> 0 | S20: =Q20*R20 -> 0 | U20: 19.10-20.10 | Z20: 18 | AE20: =H818 -> 0 | AH20: =P818 -> 0
O21: =M21*N21 -> 0 | S21: =Q21*R21 -> 0 | Z21: 19 | AE21: =H864 -> 0 | AH21: =P864 -> 0
G22: พฤหัส | H22: 30101-2607 | I22: ปวส. 2/6 สยฟ. (ม.6) | J22: 08.10-12.10 | O22: =M22*N22 -> 0 | Q22: 4 | R22: 270 | S22: =Q22*R22 -> 1080 | Z22: 20 | AE22: =H910 -> 0 | AH22: =P910 -> 0
G23: 21 ธ.ค.66 | H23: 30000-2002 | I23: ปวส.1/1,2 สยฟ. (ทวิ) | J23: 13.10-15.10 | O23: =M23*N23 -> 0 | P23: 2 | S23: =Q23*R23 -> 0 | Z23: 21 | AE23: =H956 -> 0 | AH23: =P956 -> 0
O24: =M24*N24 -> 0 | S24: =Q24*R24 -> 0 | U24: PLC | Z24: 22 | AE24: =H1002 -> 0 | AH24: =P1002 -> 0
O25: =M25*N25 -> 0 | S25: =Q25*R25 -> 0 | U25: 17.10-19.10 | Z25: 23 | AE25: =H1048 -> 0 | AH25: =P1048 -> 0
O26: =M26*N26 -> 0 | S26: =Q26*R26 -> 0 | Z26: 24 | AE26: =H1094 -> 0 | AH26: =P1094 -> 0
G27: ศุกร์ | H27: 30143-2005 | I27: ปวส.1/1 สยฟ. (ทวิ) | J27: 08.10-12.10 | O27: =M27*N27 -> 0 | P27: 4 | S27: =Q27*R27 -> 0 | Z27: 25 | AE27: =H1140 -> 0 | AH27: =P1140 -> 0
G28: 22 ธ.ค.66 | H28: 30143-2005 | I28: ปวส.1/1 สยฟ. (ทวิ) | J28: 13.10-14.10 | O28: =M28*N28 -> 0 | P28: 1 | S28: =Q28*R28 -> 0 | Z28: 26 | AC28: นายชินวัฒน์ พิลึก | AD28: นายชินวัฒน์ พิลึก | AE28: =H1186 -> 0 | AH28: =P1186 -> 0
O29: =M29*N29 -> 0 | S29: =Q29*R29 -> 0 | U29: เบิก ธุรการ | Z29: 27 | AC29: นายชินวัฒน์ พิลึก | AD29: นายชินวัฒน์ พิลึก | AE29: =H1232 -> 0 | AH29: =P1232 -> 0
O30: =M30*N30 -> 0 | S30: =Q30*R30 -> 0 | U30: 16.10-19.10
O31: =M31*N31 -> 0 | S31: =Q31*R31 -> 0
G32: รวมขั่วโมงที่สอนแยก ภาระงาน/ เกินภาระงาน | L32: =SUM(L7:L31) -> 0 | M32: =SUM(M7:M31) -> 0 | P32: =SUM(P7:P31) -> 18 | Q32: =SUM(Q7:Q31) -> 12
G33: รวมจำนวนชั่วโมงสอนคาบต่อสับดาห์ | L33: =L32+M32 -> 0 | P33: =P32+Q32 -> 30
G34: จำนวนชั่วโมงสอนตามภาระงานสอน | L34: 0 | P34: 10
G35: จำนวนชั่วโมงบิกเกินภาระงานสอน/ค่าสอน | L35: 0 | M35: =SUM(M7:M31) -> 0 | O35: =SUM(O7:O31) -> 0 | P35: 0 | Q35: =SUM(Q7:Q31) -> 12 | S35: =SUM(S7:S31) -> 3240
A36: รวมจำนวนหน่วยชั่วโมงที่ขอเบิกค่าสอน …. | H36: =M35+Q35 -> 12 | I36: ….ชั่วโมง | K36: ยอดเงินรวม | P36: =S35+O35 -> 3240 | S36: ..บาท
A37: ผู้ขอเบิก | H37: ผู้รับรอง | M37: ผู้ตรวจ
A38: ลงชื่อ…………………………………………… | H38: ลงชื่อ…………………………………………… | M38: ลงชื่อ……………………………………………
A39: ( | B39: =B7 -> นายอาทิตย์ แก้วแดง | G39: ) | H39: ( | I39: นายอาทิตย์ แก้วแดง | L39: ) | M39: ( | O39: นายทศวรรษ คำสม | S39: )
A40: ตำแหน่ง ครู | H40: ตำแหน่ง หัวหน้าแผนก | M40: ตำแหน่ง ผู้ตรวจสอบ
...

Sheet สัปดาห์ที่ 4
A1: ใบเบิกจ่ายเงินค่าสอนพิเศษและค่าสอนเกินภาระงานสอนในสถานศึกษา
A2: แผนกวิชายานยนต์ไฟฟ้า | Z2: ลำดับ | AB2: รายชื่อ | AE2: รวม ชม./ ส. | AH2: รวม ค่าสอน / สัปดาห์
A3: ระหว่างวันที่ | D3: 25 | E3: เดือน | F3: ธันวาคม | H3: พ.ศ. 2566 | I3: ถึง วันที่ | J3: 29 | K3: เดือน | L3: ธันวาคม | N3: พ.ศ. 2566 | Z3: 1 | AB3: นายอาทิตย์ แก้วแดง | AC3: นายอาทิตย์ แก้วแดง | AD3: นายอาทิตย์ แก้วแดง | AE3: =H36 -> 3 | AH3: =P36 -> 810
G4: ü | H4: ครู | I4: หน้าที่พิเศษ | J4: หัวหน้าแผนกยานยนต์ไฟฟ้า | Z4: 2 | AB4: นางสาวปาจารีย์ กฐินทอง | AE4: =H82 -> 3 | AH4: =P82 -> 600
A5: ที่ | B5: ชื่อ-สกุล | E5: ตำแหน่ง | F5: ระยะเวลาที่สอน | H5: รหัสวิชา | I5: ชั้น,แผนก,ห้อง | J5: เวลาสอน | L5: ปวช.(คาบ) | N5: เงิน | O5: ยอดเงิน | P5: ปวส.(คาบ) | R5: เงิน | S5: ยอดเงิน | Z5: 3 | AE5: =H128 -> 0 | AH5: =P128 -> 0
F6: ส. | G6: วดป. | L6: ใน | M6: นอก | N6: ต่อ ชม. | O6: (บาท) | P6: ใน | Q6: นอก | R6: ต่อ ชม. | S6: (บาท) | Z6: 4 | AC6: นายธนิต กฐินทอง | AD6: นายธนิต กฐินทอง | AE6: =H174 -> 0 | AH6: =P174 -> 0
A7: 1 | B7: =AB3 -> นายอาทิตย์ แก้วแดง | E7: ครู | F7: 11 | G7: จันทร์ | H7: ไปราชการ | O7: =M7*N7 -> 0 | S7: =Q7*R7 -> 0 | Z7: 5 | AC7: นายสุริยา คำอุดม | AD7: นายสุริยา คำอุดม | AE7: =H220 -> 0 | AH7: =P220 -> 0
G8: 25 ธ.ค.66 | O8: =M8*N8 -> 0 | S8: =Q8*R8 -> 0 | Z8: 6 | AC8: นายดำเนิน สุขขี | AD8: นายดำเนิน สุขขี | AE8: =H266 -> 0 | AH8: =P266 -> 0
H9: นายสุริยา คำอุดม สอนแทน (9 ชม.) | O9: =M9*N9 -> 0 | S9: =Q9*R9 -> 0 | T9: สอน ป.ตรี | Z9: 7 | AC9: นายอาทิตย์ แก้วแดง | AD9: นายอาทิตย์ แก้วแดง | AE9: =H312 -> 0 | AH9: =P312 -> 0
O10: =M10*N10 -> 0 | S10: =Q10*R10 -> 0 | U10: 19.10-20.10 | Z10: 8 | AE10: =H358 -> 0 | AH10: =P358 -> 0
O11: =M11*N11 -> 0 | S11: =Q11*R11 -> 0 | Z11: 9 | AE11: =H404 -> 0 | AH11: =P404 -> 0
G12: อังคาร | O12: =M12*N12 -> 0 | S12: =Q12*R12 -> 0 | Z12: 10 | AE12: =H450 -> 0 | AH12: =P450 -> 0
G13: 26 ธ.ค.66 | O13: =M13*N13 -> 0 | S13: =Q13*R13 -> 0 | Z13: 11 | AE13: =H496 -> 0 | AH13: =P496 -> 0
O14: =M14*N14 -> 0 | S14: =Q14*R14 -> 0 | Z14: 12 | AE14: =H542 -> 0 | AH14: =P542 -> 0
O15: =M15*N15 -> 0 | S15: =Q15*R15 -> 0 | Z15: 13 | AE15: =H588 -> 0 | AH15: =P588 -> 0
O16: =M16*N16 -> 0 | S16: =Q16*R16 -> 0 | Z16: 14 | AE16: =H634 -> 0 | AH16: =P634 -> 0
G17: พุธ | H17: 30143-2004 | I17: ปวส.1/1 สยฟ. (ทวิ) | J17: 08.10-12.10 | O17: =M17*N17 -> 0 | P17: 1 | Q17: 3 | R17: 270 | S17: =Q17*R17 -> 810 | Z17: 15 | AE17: =H680 -> 0 | AH17: =P680 -> 0
G18: 27 ธ.ค.66 | H18: 30143-2004 | I18: ปวส.1/1 สยฟ. (ทวิ) | J18: 13.10-14.10 | O18: =M18*N18 -> 0 | P18: 1 | S18: =Q18*R18 -> 0 | Z18: 16 | AE18: =H726 -> 0 | AH18: =P726 -> 0
H19: 30143-2004 | I19: ปวส.1/2 สยฟ. (ทวิ) | J19: 14.10-19.10 | O19: =M19*N19 -> 0 | P19: 5 | S19: =Q19*R19 -> 0 | T19: สอน ป.ตรี | Z19: 17 | AE19: =H772 -> 0 | AH19: =P772 -> 0
O20: =M20*N20 -> 0 | S20: =Q20*R20 -> 0 | U20: 19.10-20.10 | Z20: 18 | AE20: =H818 -> 0 | AH20: =P818 -> 0
O21: =M21*N21 -> 0 | S21: =Q21*R21 -> 0 | Z21: 19 | AE21: =H864 -> 0 | AH21: =P864 -> 0
G22: พฤหัส | H22: 30101-2607 | I22: ปวส. 2/6 สยฟ. (ม.6) | J22: 08.10-12.10 | O22: =M22*N22 -> 0 | P22: 4 | S22: =Q22*R22 -> 0 | Z22: 20 | AE22: =H910 -> 0 | AH22: =P910 -> 0
G23: 28 ธ.ค.66 | H23: 30000-2002 | I23: ปวส.1/1,2 สยฟ. (ทวิ) | J23: 13.10-15.10 | O23: =M23*N23 -> 0 | P23: 2 | S23: =Q23*R23 -> 0 | Z23: 21 | AE23: =H956 -> 0 | AH23: =P956 -> 0
O24: =M24*N24 -> 0 | S24: =Q24*R24 -> 0 | U24: PLC | Z24: 22 | AE24: =H1002 -> 0 | AH24: =P1002 -> 0
O25: =M25*N25 -> 0 | S25: =Q25*R25 -> 0 | U25: 17.10-19.10 | Z25: 23 | AE25: =H1048 -> 0 | AH25: =P1048 -> 0
O26: =M26*N26 -> 0 | S26: =Q26*R26 -> 0 | Z26: 24 | AE26: =H1094 -> 0 | AH26: =P1094 -> 0
G27: ศุกร์ | H27: หยุด | O27: =M27*N27 -> 0 | S27: =Q27*R27 -> 0 | Z27: 25 | AE27: =H1140 -> 0 | AH27: =P1140 -> 0
G28: 29 ธ.ค.66 | O28: =M28*N28 -> 0 | S28: =Q28*R28 -> 0 | Z28: 26 | AC28: นายชินวัฒน์ พิลึก | AD28: นายชินวัฒน์ พิลึก | AE28: =H1186 -> 0 | AH28: =P1186 -> 0
O29: =M29*N29 -> 0 | S29: =Q29*R29 -> 0 | U29: เบิก ธุรการ | Z29: 27 | AC29: นายชินวัฒน์ พิลึก | AD29: นายชินวัฒน์ พิลึก | AE29: =H1232 -> 0 | AH29: =P1232 -> 0
O30: =M30*N30 -> 0 | S30: =Q30*R30 -> 0 | U30: 16.10-19.10
O31: =M31*N31 -> 0 | S31: =Q31*R31 -> 0
G32: รวมขั่วโมงที่สอนแยก ภาระงาน/ เกินภาระงาน | L32: =SUM(L7:L31) -> 0 | M32: =SUM(M7:M31) -> 0 | P32: =SUM(P7:P31) -> 13 | Q32: =SUM(Q7:Q31) -> 3
G33: รวมจำนวนชั่วโมงสอนคาบต่อสับดาห์ | L33: =L32+M32 -> 0 | P33: =P32+Q32 -> 16
G34: จำนวนชั่วโมงสอนตามภาระงานสอน | L34: 0 | P34: 10
G35: จำนวนชั่วโมงบิกเกินภาระงานสอน/ค่าสอน | L35: 0 | M35: =SUM(M7:M31) -> 0 | O35: =SUM(O7:O31) -> 0 | P35: 0 | Q35: =SUM(Q7:Q31) -> 3 | S35: =SUM(S7:S31) -> 810
A36: รวมจำนวนหน่วยชั่วโมงที่ขอเบิกค่าสอน …. | H36: =M35+Q35 -> 3 | I36: ….ชั่วโมง | K36: ยอดเงินรวม | P36: =S35+O35 -> 810 | S36: ..บาท
A37: ผู้ขอเบิก | H37: ผู้รับรอง | M37: ผู้ตรวจ
A38: ลงชื่อ…………………………………………… | H38: ลงชื่อ…………………………………………… | M38: ลงชื่อ……………………………………………
A39: ( | B39: =B7 -> นายอาทิตย์ แก้วแดง | G39: ) | H39: ( | I39: นายอาทิตย์ แก้วแดง | L39: ) | M39: ( | O39: นายทศวรรษ คำสม | S39: )
A40: ตำแหน่ง ครู | H40: ตำแหน่ง หัวหน้าแผนก | M40: ตำแหน่ง ผู้ตรวจสอบ
...

Sheet ตารางแจงเงินรายบุคคล
D1: ครูประจำ
A4: ลำดับ | B4: ชื่อ-สกุล | C4: 1 | E4: 2 | G4: 3 | I4: 4 | K4: 5 | M4: 6 | O4: รวม / ชม. | P4: รวม
C5: ชม/ส | D5: เงิน | E5: ชม/ส | F5: เงิน | G5: ชม/ส | H5: เงิน | I5: ชม/ส | J5: เงิน | K5: ชม/ส | L5: เงิน | M5: ชม/ส | N5: เงิน
A6: 1 | B6: =#REF! -> #REF! | C6: ='สัปดาห์ที่ 1'!AE3 -> 12 | D6: ='สัปดาห์ที่ 1'!AH3 -> 3240 | E6: ='สัปดาห์ที่ 2'!AE3 -> 12 | F6: ='สัปดาห์ที่ 2'!AH3 -> 3240 | G6: ='สัปดาห์ที่ 3'!AE3 -> 12 | H6: ='สัปดาห์ที่ 3'!AH3 -> 3240 | I6: ='สัปดาห์ที่ 4'!AE3 -> 3 | J6: ='สัปดาห์ที่ 4'!AH3 -> 810 | K6: 0 | L6: 0 | M6: 0 | N6: 0 | O6: =C6+E6+G6+I6+K6+M6 -> 39 | P6: =D6+F6+H6+J6+L6+N6 -> 10530
A7: 2 | B7: =#REF! -> #REF! | C7: ='สัปดาห์ที่ 1'!AE4 -> 0 | D7: ='สัปดาห์ที่ 1'!AH4 -> 0 | E7: ='สัปดาห์ที่ 2'!AE4 -> 7 | F7: ='สัปดาห์ที่ 2'!AH4 -> 1400 | G7: ='สัปดาห์ที่ 3'!AE4 -> 12 | H7: ='สัปดาห์ที่ 3'!AH4 -> 2400 | I7: ='สัปดาห์ที่ 4'!AE4 -> 3 | J7: ='สัปดาห์ที่ 4'!AH4 -> 600 | K7: 0 | L7: 0 | M7: 0 | N7: 0 | O7: =C7+E7+G7+I7+K7 -> 22 | P7: =D7+F7+H7+J7+L7 -> 4400
A8: 3 | B8: =#REF! -> #REF! | C8: ='สัปดาห์ที่ 1'!AE5 -> 0 | D8: ='สัปดาห์ที่ 1'!AH5 -> 0 | E8: ='สัปดาห์ที่ 2'!AE5 -> 0 | F8: ='สัปดาห์ที่ 2'!AH5 -> 0 | G8: ='สัปดาห์ที่ 3'!AE5 -> 0 | H8: ='สัปดาห์ที่ 3'!AH5 -> 0 | I8: ='สัปดาห์ที่ 4'!AE5 -> 0 | J8: ='สัปดาห์ที่ 4'!AH5 -> 0 | K8: 0 | L8: 0 | M8: 0 | N8: 0 | O8: =C8+E8+G8+I8+K8 -> 0 | P8: =D8+F8+H8+J8+L8 -> 0
A9: 4 | B9: =#REF! -> #REF! | C9: ='สัปดาห์ที่ 1'!AE6 -> 0 | D9: ='สัปดาห์ที่ 1'!AH6 -> 0 | E9: ='สัปดาห์ที่ 2'!AE6 -> 0 | F9: ='สัปดาห์ที่ 2'!AH6 -> 0 | G9: ='สัปดาห์ที่ 3'!AE6 -> 0 | H9: ='สัปดาห์ที่ 3'!AH6 -> 0 | I9: ='สัปดาห์ที่ 4'!AE6 -> 0 | J9: ='สัปดาห์ที่ 4'!AH6 -> 0 | K9: 0 | L9: 0 | M9: 0 | N9: 0 | O9: =C9+E9+G9+I9+K9 -> 0 | P9: =D9+F9+H9+J9+L9 -> 0
A10: 5 | B10: =#REF! -> #REF! | C10: ='สัปดาห์ที่ 1'!AE7 -> 0 | D10: ='สัปดาห์ที่ 1'!AH7 -> 0 | E10: ='สัปดาห์ที่ 2'!AE7 -> 0 | F10: ='สัปดาห์ที่ 2'!AH7 -> 0 | G10: ='สัปดาห์ที่ 3'!AE7 -> 0 | H10: ='สัปดาห์ที่ 3'!AH7 -> 0 | I10: ='สัปดาห์ที่ 4'!AE7 -> 0 | J10: ='สัปดาห์ที่ 4'!AH7 -> 0 | K10: 0 | L10: 0 | M10: 0 | N10: 0 | O10: =C10+E10+G10+I10+K10 -> 0 | P10: =D10+F10+H10+J10+L10 -> 0
A11: 6 | B11: =#REF! -> #REF! | C11: ='สัปดาห์ที่ 1'!AE8 -> 0 | D11: ='สัปดาห์ที่ 1'!AH8 -> 0 | E11: ='สัปดาห์ที่ 2'!AE8 -> 0 | F11: ='สัปดาห์ที่ 2'!AH8 -> 0 | G11: ='สัปดาห์ที่ 3'!AE8 -> 0 | H11: ='สัปดาห์ที่ 3'!AH8 -> 0 | I11: ='สัปดาห์ที่ 4'!AE8 -> 0 | J11: ='สัปดาห์ที่ 4'!AH8 -> 0 | K11: 0 | L11: 0 | M11: 0 | N11: 0 | O11: =C11+E11+G11+I11+K11 -> 0 | P11: =D11+F11+H11+J11+L11 -> 0
A12: 7 | B12: =#REF! -> #REF! | C12: ='สัปดาห์ที่ 1'!AE9 -> 0 | D12: ='สัปดาห์ที่ 1'!AH9 -> 0 | E12: ='สัปดาห์ที่ 2'!AE9 -> 0 | F12: ='สัปดาห์ที่ 2'!AH9 -> 0 | G12: ='สัปดาห์ที่ 3'!AE9 -> 0 | H12: ='สัปดาห์ที่ 3'!AH9 -> 0 | I12: ='สัปดาห์ที่ 4'!AE9 -> 0 | J12: ='สัปดาห์ที่ 4'!AH9 -> 0 | K12: 0 | L12: 0 | M12: 0 | N12: 0 | O12: =C12+E12+G12+I12+K12 -> 0 | P12: =D12+F12+H12+J12+L12 -> 0
A13: 8 | B13: =#REF! -> #REF! | C13: ='สัปดาห์ที่ 1'!AE10 -> 0 | D13: ='สัปดาห์ที่ 1'!AH10 -> 0 | E13: ='สัปดาห์ที่ 2'!AE10 -> 0 | F13: ='สัปดาห์ที่ 2'!AH10 -> 0 | G13: ='สัปดาห์ที่ 3'!AE10 -> 0 | H13: ='สัปดาห์ที่ 3'!AH10 -> 0 | I13: ='สัปดาห์ที่ 4'!AE10 -> 0 | J13: ='สัปดาห์ที่ 4'!AH10 -> 0 | K13: 0 | L13: 0 | M13: 0 | N13: 0 | O13: =C13+E13+G13+I13+K13 -> 0 | P13: =D13+F13+H13+J13+L13 -> 0
A14: 9 | B14: =#REF! -> #REF! | C14: ='สัปดาห์ที่ 1'!AE11 -> 0 | D14: ='สัปดาห์ที่ 1'!AH11 -> 0 | E14: ='สัปดาห์ที่ 2'!AE11 -> 0 | F14: ='สัปดาห์ที่ 2'!AH11 -> 0 | G14: ='สัปดาห์ที่ 3'!AE11 -> 0 | H14: ='สัปดาห์ที่ 3'!AH11 -> 0 | I14: ='สัปดาห์ที่ 4'!AE11 -> 0 | J14: ='สัปดาห์ที่ 4'!AH11 -> 0 | K14: 0 | L14: 0 | M14: 0 | N14: 0 | O14: =C14+E14+G14+I14+K14 -> 0 | P14: =D14+F14+H14+J14+L14 -> 0
A15: 10 | B15: =#REF! -> #REF! | C15: ='สัปดาห์ที่ 1'!AE12 -> 0 | D15: ='สัปดาห์ที่ 1'!AH12 -> 0 | E15: ='สัปดาห์ที่ 2'!AE12 -> 0 | F15: ='สัปดาห์ที่ 2'!AH12 -> 0 | G15: ='สัปดาห์ที่ 3'!AE12 -> 0 | H15: ='สัปดาห์ที่ 3'!AH12 -> 0 | I15: ='สัปดาห์ที่ 4'!AE12 -> 0 | J15: ='สัปดาห์ที่ 4'!AH12 -> 0 | K15: 0 | L15: 0 | M15: 0 | N15: 0 | O15: =C15+E15+G15+I15+K15 -> 0 | P15: =D15+F15+H15+J15+L15 -> 0
A16: 11 | B16: =#REF! -> #REF! | C16: ='สัปดาห์ที่ 1'!AE13 -> 0 | D16: ='สัปดาห์ที่ 1'!AH13 -> 0 | E16: ='สัปดาห์ที่ 2'!AE13 -> 0 | F16: ='สัปดาห์ที่ 2'!AH13 -> 0 | G16: ='สัปดาห์ที่ 3'!AE13 -> 0 | H16: ='สัปดาห์ที่ 3'!AH13 -> 0 | I16: ='สัปดาห์ที่ 4'!AE13 -> 0 | J16: ='สัปดาห์ที่ 4'!AH13 -> 0 | K16: 0 | L16: 0 | M16: 0 | N16: 0 | O16: =C16+E16+G16+I16+K16 -> 0 | P16: =D16+F16+H16+J16+L16 -> 0
A17: 12 | B17: =#REF! -> #REF! | C17: ='สัปดาห์ที่ 1'!AE14 -> 0 | D17: ='สัปดาห์ที่ 1'!AH14 -> 0 | E17: ='สัปดาห์ที่ 2'!AE14 -> 0 | F17: ='สัปดาห์ที่ 2'!AH14 -> 0 | G17: ='สัปดาห์ที่ 3'!AE14 -> 0 | H17: ='สัปดาห์ที่ 3'!AH14 -> 0 | I17: ='สัปดาห์ที่ 4'!AE14 -> 0 | J17: ='สัปดาห์ที่ 4'!AH14 -> 0 | K17: 0 | L17: 0 | M17: 0 | N17: 0 | O17: =C17+E17+G17+I17+K17 -> 0 | P17: =D17+F17+H17+J17+L17 -> 0
A18: 13 | B18: =#REF! -> #REF! | C18: ='สัปดาห์ที่ 1'!AE15 -> 0 | D18: ='สัปดาห์ที่ 1'!AH15 -> 0 | E18: ='สัปดาห์ที่ 2'!AE15 -> 0 | F18: ='สัปดาห์ที่ 2'!AH15 -> 0 | G18: ='สัปดาห์ที่ 3'!AE15 -> 0 | H18: ='สัปดาห์ที่ 3'!AH15 -> 0 | I18: ='สัปดาห์ที่ 4'!AE15 -> 0 | J18: ='สัปดาห์ที่ 4'!AH15 -> 0 | K18: 0 | L18: 0 | M18: 0 | N18: 0 | O18: =C18+E18+G18+I18+K18 -> 0 | P18: =D18+F18+H18+J18+L18 -> 0
... A24: 19 | B24: =#REF! -> #REF! | C24: ='สัปดาห์ที่ 1'!AE21 -> 0 | D24: ='สัปดาห์ที่ 1'!AH21 -> 0 | E24: ='สัปดาห์ที่ 2'!AE21 -> 0 | F24: ='สัปดาห์ที่ 2'!AH21 -> 0 | G24: ='สัปดาห์ที่ 3'!AE21 -> 0 | H24: ='สัปดาห์ที่ 3'!AH21 -> 0 | I24: ='สัปดาห์ที่ 4'!AE21 -> 0 | J24: ='สัปดาห์ที่ 4'!AH21 -> 0 | K24: 0 | L24: 0 | M24: 0 | N24: 0 | O24: =C24+E24+G24+I24+K24 -> 0 | P24: =D24+F24+H24+J24+L24 -> 0
A25: รวมเงินครูประจำ | P25: =SUM(P6:P24) -> 14930
D27: ครูพิเศษ
A30: ลำดับ | B30: ชื่อ-สกุล | C30: 1 | E30: 2 | G30: 3 | I30: 4 | K30: 5 | M30: 6 | O30: รวม / ชม. | P30: รวม
C31: ชม/ส | D31: เงิน | E31: ชม/ส | F31: เงิน | G31: ชม/ส | H31: เงิน | I31: ชม/ส | J31: เงิน | K31: ชม/ส | L31: เงิน | M31: ชม/ส | N31: เงิน
A32: 1 | B32: =#REF! -> #REF! | C32: =#REF! -> #REF! | D32: =#REF! -> #REF! | E32: =#REF! -> #REF! | F32: =#REF! -> #REF! | G32: =#REF! -> #REF! | H32: =#REF! -> #REF! | I32: 0 | J32: 0 | K32: 0 | L32: 0 | O32: =C32+E32+G32+I32+K32 -> #REF! | P32: =D32+F32+H32+J32+L32 -> #REF!
A33: 2 | B33: =#REF! -> #REF! | C33: =#REF! -> #REF! | D33: =#REF! -> #REF! | E33: =#REF! -> #REF! | F33: =#REF! -> #REF! | G33: =#REF! -> #REF! | H33: =#REF! -> #REF! | I33: 0 | J33: 0 | K33: 0 | L33: 0 | O33: =C33+E33+G33+I33+K33 -> #REF! | P33: =D33+F33+H33+J33+L33 -> #REF!
A34: 3 | B34: =#REF! -> #REF! | C34: =#REF! -> #REF! | D34: =#REF! -> #REF! | E34: =#REF! -> #REF! | F34: =#REF! -> #REF! | G34: =#REF! -> #REF! | H34: =#REF! -> #REF! | I34: 0 | J34: 0 | K34: 0 | L34: 0 | O34: =C34+E34+G34+I34+K34 -> #REF! | P34: =D34+F34+H34+J34+L34 -> #REF!
A35: 4 | B35: =#REF! -> #REF! | C35: =#REF! -> #REF! | D35: =#REF! -> #REF! | E35: =#REF! -> #REF! | F35: =#REF! -> #REF! | G35: =#REF! -> #REF! | H35: =#REF! -> #REF! | I35: 0 | J35: 0 | K35: 0 | L35: 0 | O35: =C35+E35+G35+I35+K35 -> #REF! | P35: =D35+F35+H35+J35+L35 -> #REF!
A36: 5 | B36: =#REF! -> #REF! | C36: =#REF! -> #REF! | D36: =#REF! -> #REF! | E36: =#REF! -> #REF! | F36: =#REF! -> #REF! | G36: =#REF! -> #REF! | H36: =#REF! -> #REF! | I36: 0 | J36: 0 | K36: 0 | L36: 0 | O36: =C36+E36+G36+I36+K36 -> #REF! | P36: =D36+F36+H36+J36+L36 -> #REF!
A37: 6 | B37: =#REF! -> #REF! | C37: =#REF! -> #REF! | D37: =#REF! -> #REF! | E37: =#REF! -> #REF! | F37: =#REF! -> #REF! | G37: =#REF! -> #REF! | H37: =#REF! -> #REF! | I37: 0 | J37: 0 | K37: 0 | L37: 0 | O37: =C37+E37+G37+I37+K37 -> #REF! | P37: =D37+F37+H37+J37+L37 -> #REF!
A38: 7 | B38: =#REF! -> #REF! | C38: =#REF! -> #REF! | D38: =#REF! -> #REF! | E38: =#REF! -> #REF! | F38: =#REF! -> #REF! | G38: =#REF! -> #REF! | H38: =#REF! -> #REF! | I38: 0 | J38: 0 | K38: 0 | L38: 0 | O38: =C38+E38+G38+I38+K38 -> #REF! | P38: =D38+F38+H38+J38+L38 -> #REF!
A39: 8 | B39: =#REF! -> #REF! | C39: =#REF! -> #REF! | D39: =#REF! -> #REF! | E39: =#REF! -> #REF! | F39: =#REF! -> #REF! | G39: =#REF! -> #REF! | H39: =#REF! -> #REF! | I39: 0 | J39: 0 | K39: 0 | L39: 0 | O39: =C39+E39+G39+I39+K39 -> #REF! | P39: =D39+F39+H39+J39+L39 -> #REF!
A40: 9 | B40: =#REF! -> #REF! | C40: =#REF! -> #REF! | D40: =#REF! -> #REF! | E40: =#REF! -> #REF! | F40: =#REF! -> #REF! | G40: =#REF! -> #REF! | H40: =#REF! -> #REF! | I40: 0 | J40: 0 | K40: 0 | L40: 0 | O40: =C40+E40+G40+I40+K40 -> #REF! | P40: =D40+F40+H40+J40+L40 -> #REF!
A41: รวมเงินครูพิเศษ | P41: =SUM(P32:P40) -> #REF!
A43: ยอดเงินรายรับ ( ครูประจำ + ครูพิเศษ ) | H43: =P25+P41 -> #REF!
A44: ยอดเงินรายรับ ÷ ยอดคน | D44: =H43 -> #REF! | E44: ÷ | F44: 26 | H44: = | J44: =D44/F44 -> #REF!
A45: หักเข้ากองกลาง (3 ส.x100) x 26 คน | D45: 300 | E45: x | F45: 26 | H45: = | J45: =D45*F45 -> 7800
A48: เงินที่ได้รับ คนละ | D48: =J44 -> #REF! | E48: - | F48: =D45 -> 300 | J48: = | K48: =J44-D45-D46 -> #REF!
A49: ปัดให้ลงตัว | D49: =K48 -> #REF! | E49: + | F49: 22 | J49: = | K49: =D49+F49 -> #REF!
A51: เงินกองกลาง | J51: = | K51: =J45 -> 7800
A52: เงินเข้ากองกลางคงเหลือ | D52: =J45 -> 7800 | E52: - | F52: =F49*F44 -> 572 | J52: = | K52: =D52-F52 -> 7228
A55: ลำดับ | B55: ชื่อ-สกุล | C55: การจัดสรรค์เงินรายได้แผนก | I55: ลงชื่อ
C56: รายรับ / บุคคล | E56: คืนกองกลางแผนก ( - ) | G56: แผนกจ่ายเพิ่ม ( + )
...

Sheet งบหน้ารวมครู
A1: หลักฐานการเบิกจ่ายเงินค่าสอนพิเศษและค่าสอนเกินภาระงานสอนในสถานศึกษา
C2: ส่วนราชการ วิทยาลัยเทคนิคนครสวรรค์ | H2: ประจำเดือน | I2: 27 พฤศจิกายน 2566 - 29 ธันวาคม 2566
G4: ระดับการสอน | I4: จำนวนหน่วย | J4: จำนวนเงิน | K4: ลายมือชื่อผู้รับเงิน | L4: วัน/เดือน/ปี | M4: หมายเหตุ
A5: ลำดับที่ | B5: ชื่อ - นามสกุล | F5: ตำแหน่ง | G5: มัธยมศึกษาตอนต้น | H5: สูงกว่า | I5: ชั่วโมงที่ทำการสอน
F6: ผู้ทำการสอน | G6: หรือมัธยมศึกษาตอนปลาย | H6: มัธยมศึกษาตอนปลาย | I6: พิเศษและสอนเกิน | L6: ที่รับเงิน
G7: หรือเทียบเท่า | H7: หรือเทียบเท่า | I7: ภาระงานสอน | O7: =#REF! -> #REF!
A8: 1 | B8: =ตารางแจงเงินรายบุคคล!B6 -> #REF! | F8: ครู | G8: ü | I8: =ตารางแจงเงินรายบุคคล!O6 -> 39 | J8: =ตารางแจงเงินรายบุคคล!P6 -> 10530 | O8: =#REF! -> #REF!
A9: 2 | B9: =ตารางแจงเงินรายบุคคล!B7 -> #REF! | F9: พนง.ราชการ | G9: ü | I9: =ตารางแจงเงินรายบุคคล!O7 -> 22 | J9: =ตารางแจงเงินรายบุคคล!P7 -> 4400 | O9: =#REF! -> #REF!
A10: 3 | O10: =#REF! -> #REF!
A11: 4 | O11: =#REF! -> #REF!
A12: 5 | O12: =#REF! -> #REF!
A13: 6 | O13: =#REF! -> #REF!
A14: 7 | O14: =#REF! -> #REF!
A15: 8 | O15: =#REF! -> #REF!
E16: รวมจำนวนเงิน | G16: =B19 -> หนึ่งหมื่นสี่พันเก้าร้อยสามสิบบาทถ้วน | J16: =SUM(J8:J15) -> 14930 | O16: =#REF! -> #REF!
F17: ผู้ทำ | J17: ผู้จ่ายเงิน | O17: =#REF! -> #REF!
A18: รวมจำนวนเงินค่าสอนพิเศษทั้งสิ้น | C18: =J16 -> 14930 | D18: บาท | F18: ลงชื่อ......................................... | J18: ลงชื่อ......................................... | O18: =#REF! -> #REF!
A19: ( | B19: =BAHTTEXT(C18) -> หนึ่งหมื่นสี่พันเก้าร้อยสามสิบบาทถ้วน | E19: ) | F19: (นายอาทิตย์ แก้วแดง) | J19: (นางวีณา กฐินทอง ) | O19: =#REF! -> #REF!
F20: ตำแหน่งครู หัวหน้าแผนกวิชายานยนต์ไฟฟ้า | J20: ตำแหน่ง หัวหน้างานการเงิน | O20: =#REF! -> #REF!
F21: วันที่.......เดือน..........................พ.ศ.............. | J21: วันที่........เดือน...............พ.ศ...........
A22: ผู้รับรอง | F22: ผู้เห็นชอบ | J22: ผู้อนุมัติ | O22: =O7+O8+O9+O10+O11+O12+O13+O14+O15+O16+O17+O18+O19+O20 -> #REF!
A23: ลงชื่อ........................................................................... | F23: ลงชื่อ............................................................... | J23: ลงชื่อ...................................................................
B24: (นายปรีชา โพธิ์เกิด) | G24: (นางกุสุมา ขันกสิกรรม) | K24: (นายปริวิชญ์ ไชยประเสริฐ)
A25: ตำแหน่ง รองผู้อำนวยการฝ่ายวิชาการ | F25: ตำแหน่ง รองผู้อำนวยการฝ่ายบริหารทรัพยากร | J25: ตำแหน่ง ผู้อำนวยการวิทยาลัยเทคนิคนครสวรรค์
A26: วันที่..................เดือน..........................พ.ศ................ | F26: วันที่.............เดือน.......................พ.ศ............. | J26: วันที่...........เดือน...................พ.ศ..........
A27: หลักฐานการเบิกจ่ายเงินค่าสอนพิเศษและค่าสอนเกินภาระงานสอนในสถานศึกษา
C28: ส่วนราชการ วิทยาลัยเทคนิคนครสวรรค์ | H28: ประจำเดือน | I28: =I2 -> 27 พฤศจิกายน 2566 - 29 ธันวาคม 2566
G30: ระดับการสอน | I30: จำนวนหน่วย | J30: จำนวนเงิน | M30: หมายเหตุ
A31: ลำดับที่ | B31: ชื่อ - นามสกุล | F31: ตำแหน่ง | G31: มัธยมศึกษาตอนต้น | H31: สูงกว่า | I31: ชั่วโมงที่ทำการสอน | K31: ลายมือชื่อ | L31: วัน/เดือน/ปี
F32: ผู้ทำการสอน | G32: หรือมัธยมศึกษาตอนปลาย | H32: มัธยมศึกษาตอนปลาย | I32: พิเศษและสอนเกิน | K32: ผู้รับเงิน | L32: ที่รับเงิน
G33: หรือเทียบเท่า | H33: หรือเทียบเท่า | I33: ภาระงานสอน
B34: ย/ม | J34: =J16 -> 14930
A35: 9 | B35: =ตารางแจงเงินรายบุคคล!B14 -> #REF! | F35: ครู | G35: ü | I35: =ตารางแจงเงินรายบุคคล!O14 -> 0 | J35: =ตารางแจงเงินรายบุคคล!P14 -> 0
A36: 10 | B36: =ตารางแจงเงินรายบุคคล!B15 -> #REF! | F36: ครู | G36: ü | I36: =ตารางแจงเงินรายบุคคล!O15 -> 0 | J36: =ตารางแจงเงินรายบุคคล!P15 -> 0
A37: 11 | B37: =ตารางแจงเงินรายบุคคล!B16 -> #REF! | F37: ครู | G37: ü | I37: =ตารางแจงเงินรายบุคคล!O16 -> 0 | J37: =ตารางแจงเงินรายบุคคล!P16 -> 0
A38: 12 | B38: =ตารางแจงเงินรายบุคคล!B17 -> #REF! | F38: ครู | G38: ü | I38: =ตารางแจงเงินรายบุคคล!O17 -> 0 | J38: =ตารางแจงเงินรายบุคคล!P17 -> 0
A39: 13 | B39: =ตารางแจงเงินรายบุคคล!B18 -> #REF! | F39: ครู | G39: ü | I39: =ตารางแจงเงินรายบุคคล!O18 -> 0 | J39: =ตารางแจงเงินรายบุคคล!P18 -> 0
A40: 14 | B40: =ตารางแจงเงินรายบุคคล!B19 -> #REF! | F40: ครู | H40: ü | I40: =ตารางแจงเงินรายบุคคล!O19 -> 0 | J40: =ตารางแจงเงินรายบุคคล!P19 -> 0
A41: 15 | B41: =ตารางแจงเงินรายบุคคล!B20 -> #REF! | F41: ครู | H41: ü | I41: =ตารางแจงเงินรายบุคคล!O20 -> 0 | J41: =ตารางแจงเงินรายบุคคล!P20 -> 0
C42: ย/ป | E42: รวมจำนวนเงิน | G42: =B45 -> หนึ่งหมื่นสี่พันเก้าร้อยสามสิบบาทถ้วน | J42: =SUM(J34:J41) -> 14930
...
